Workbook

Sheet main
A1: Z相振幅 | B1: =C1*0.005 -> 0.135 | C1: 27 | K1: 振幅 | L1: 63 | R1: 1 | S1: 16 | T1: =R1/S1 -> 0.0625

Sheet table
A1: Index Amp. | C1: Value Table | H1: Phase Step | J1: Index Table | N1: Index | Q1: Sign | T1: Value
C2: 0 | D2: 1 | E2: 2 | F2: 3 | J2: U | K2: V | L2: W | N2: U | O2: V | P2: W | Q2: U | R2: V | S2: W | T2: U | U2: V | V2: W | W2: =0.5/MAX(T3:T26) -> 0.0039370079
A3: 0 | B3: 0 | C3: =INT(((SIN(2*PI()*C$67/24)+SIN(6*PI()*C$67/24)*main!$B$1)*value!$J$1*$A3)+0.5) -> 0 | D3: =INT(((SIN(2*PI()*D$67/24)+SIN(6*PI()*D$67/24)*main!$B$1)*value!$J$1*$A3)+0.5) -> 0 | E3: =INT(((SIN(2*PI()*E$67/24)+SIN(6*PI()*E$67/24)*main!$B$1)*value!$J$1*$A3)+0.5) -> 0 | F3: =INT(((SIN(2*PI()*F$67/24)+SIN(6*PI()*F$67/24)*main!$B$1)*value!$J$1*$A3)+0.5) -> 0 | I3: 0 | J3: 1 | K3: 1 | L3: 7 | N3: =MOD(J3,4) -> 1 | O3: =MOD(K3,4) -> 1 | P3: =MOD(L3,4) -> 3 | Q3: =IF(J3<8, IF(J3<4,1,-1), 0) -> 1 | R3: =IF(K3<8, IF(K3<4,1,-1), 0) -> 1 | S3: =IF(L3<8, IF(L3<4,1,-1), 0) -> -1 | T3: =VLOOKUP(main!$L$1,table!$B$3:$F$66,N3+2,FALSE)*Q3 -> 93 | U3: =VLOOKUP(main!$L$1,table!$B$3:$F$66,O3+2,FALSE)*R3 -> 93 | V3: =VLOOKUP(main!$L$1,table!$B$3:$F$66,P3+2,FALSE)*S3 -> -127
A4: =2*(B4+1) -> 4 | B4: 1 | C4: =INT(((SIN(2*PI()*C$67/24)+SIN(6*PI()*C$67/24)*main!$B$1)*value!$J$1*$A4)+0.5) -> 2 | D4: =INT(((SIN(2*PI()*D$67/24)+SIN(6*PI()*D$67/24)*main!$B$1)*value!$J$1*$A4)+0.5) -> 3 | E4: =INT(((SIN(2*PI()*E$67/24)+SIN(6*PI()*E$67/24)*main!$B$1)*value!$J$1*$A4)+0.5) -> 4 | F4: =INT(((SIN(2*PI()*F$67/24)+SIN(6*PI()*F$67/24)*main!$B$1)*value!$J$1*$A4)+0.5) -> 4 | I4: 1 | J4: 2 | K4: 0 | L4: 7 | N4: =MOD(J4,4) -> 2 | O4: =MOD(K4,4) -> 0 | P4: =MOD(L4,4) -> 3 | Q4: =IF(J4<8, IF(J4<4,1,-1), 0) -> 1 | R4: =IF(K4<8, IF(K4<4,1,-1), 0) -> 1 | S4: =IF(L4<8, IF(L4<4,1,-1), 0) -> -1 | T4: =VLOOKUP(main!$L$1,table!$B$3:$F$66,N4+2,FALSE)*Q4 -> 118 | U4: =VLOOKUP(main!$L$1,table!$B$3:$F$66,O4+2,FALSE)*R4 -> 52 | V4: =VLOOKUP(main!$L$1,table!$B$3:$F$66,P4+2,FALSE)*S4 -> -127
A5: =2*(B5+1) -> 6 | B5: 2 | C5: =INT(((SIN(2*PI()*C$67/24)+SIN(6*PI()*C$67/24)*main!$B$1)*value!$J$1*$A5)+0.5) -> 2 | D5: =INT(((SIN(2*PI()*D$67/24)+SIN(6*PI()*D$67/24)*main!$B$1)*value!$J$1*$A5)+0.5) -> 4 | E5: 5 | F5: =INT(((SIN(2*PI()*F$67/24)+SIN(6*PI()*F$67/24)*main!$B$1)*value!$J$1*$A5)+0.5) -> 6 | I5: 2 | J5: 3 | K5: 8 | L5: 7 | N5: =MOD(J5,4) -> 3 | O5: =MOD(K5,4) -> 0 | P5: =MOD(L5,4) -> 3 | Q5: =IF(J5<8, IF(J5<4,1,-1), 0) -> 1 | R5: =IF(K5<8, IF(K5<4,1,-1), 0) -> 0 | S5: =IF(L5<8, IF(L5<4,1,-1), 0) -> -1 | T5: =VLOOKUP(main!$L$1,table!$B$3:$F$66,N5+2,FALSE)*Q5 -> 127 | U5: =VLOOKUP(main!$L$1,table!$B$3:$F$66,O5+2,FALSE)*R5 -> 0 | V5: =VLOOKUP(main!$L$1,table!$B$3:$F$66,P5+2,FALSE)*S5 -> -127
A6: =2*(B6+1) -> 8 | B6: 3 | C6: =INT(((SIN(2*PI()*C$67/24)+SIN(6*PI()*C$67/24)*main!$B$1)*value!$J$1*$A6)+0.5) -> 3 | D6: =INT(((SIN(2*PI()*D$67/24)+SIN(6*PI()*D$67/24)*main!$B$1)*value!$J$1*$A6)+0.5) -> 6 | E6: =INT(((SIN(2*PI()*E$67/24)+SIN(6*PI()*E$67/24)*main!$B$1)*value!$J$1*$A6)+0.5) -> 7 | F6: =INT(((SIN(2*PI()*F$67/24)+SIN(6*PI()*F$67/24)*main!$B$1)*value!$J$1*$A6)+0.5) -> 8 | I6: 3 | J6: 3 | K6: 4 | L6: 6 | N6: =MOD(J6,4) -> 3 | O6: =MOD(K6,4) -> 0 | P6: =MOD(L6,4) -> 2 | Q6: =IF(J6<8, IF(J6<4,1,-1), 0) -> 1 | R6: =IF(K6<8, IF(K6<4,1,-1), 0) -> -1 | S6: =IF(L6<8, IF(L6<4,1,-1), 0) -> -1 | T6: =VLOOKUP(main!$L$1,table!$B$3:$F$66,N6+2,FALSE)*Q6 -> 127 | U6: =VLOOKUP(main!$L$1,table!$B$3:$F$66,O6+2,FALSE)*R6 -> -52 | V6: =VLOOKUP(main!$L$1,table!$B$3:$F$66,P6+2,FALSE)*S6 -> -118
A7: =2*(B7+1) -> 10 | B7: 4 | C7: =INT(((SIN(2*PI()*C$67/24)+SIN(6*PI()*C$67/24)*main!$B$1)*value!$J$1*$A7)+0.5) -> 4 | D7: =INT(((SIN(2*PI()*D$67/24)+SIN(6*PI()*D$67/24)*main!$B$1)*value!$J$1*$A7)+0.5) -> 7 | E7: =INT(((SIN(2*PI()*E$67/24)+SIN(6*PI()*E$67/24)*main!$B$1)*value!$J$1*$A7)+0.5) -> 9 | F7: =INT(((SIN(2*PI()*F$67/24)+SIN(6*PI()*F$67/24)*main!$B$1)*value!$J$1*$A7)+0.5) -> 10 | I7: 4 | J7: 3 | K7: 5 | L7: 5 | N7: =MOD(J7,4) -> 3 | O7: =MOD(K7,4) -> 1 | P7: =MOD(L7,4) -> 1 | Q7: =IF(J7<8, IF(J7<4,1,-1), 0) -> 1 | R7: =IF(K7<8, IF(K7<4,1,-1), 0) -> -1 | S7: =IF(L7<8, IF(L7<4,1,-1), 0) -> -1 | T7: =VLOOKUP(main!$L$1,table!$B$3:$F$66,N7+2,FALSE)*Q7 -> 127 | U7: =VLOOKUP(main!$L$1,table!$B$3:$F$66,O7+2,FALSE)*R7 -> -93 | V7: =VLOOKUP(main!$L$1,table!$B$3:$F$66,P7+2,FALSE)*S7 -> -93
A8: =2*(B8+1) -> 12 | B8: 5 | C8: =INT(((SIN(2*PI()*C$67/24)+SIN(6*PI()*C$67/24)*main!$B$1)*value!$J$1*$A8)+0.5) -> 5 | D8: =INT(((SIN(2*PI()*D$67/24)+SIN(6*PI()*D$67/24)*main!$B$1)*value!$J$1*$A8)+0.5) -> 9 | E8: =INT(((SIN(2*PI()*E$67/24)+SIN(6*PI()*E$67/24)*main!$B$1)*value!$J$1*$A8)+0.5) -> 11 | F8: =INT(((SIN(2*PI()*F$67/24)+SIN(6*PI()*F$67/24)*main!$B$1)*value!$J$1*$A8)+0.5) -> 12 | I8: 5 | J8: 3 | K8: 6 | L8: 4 | N8: =MOD(J8,4) -> 3 | O8: =MOD(K8,4) -> 2 | P8: =MOD(L8,4) -> 0 | Q8: =IF(J8<8, IF(J8<4,1,-1), 0) -> 1 | R8: =IF(K8<8, IF(K8<4,1,-1), 0) -> -1 | S8: =IF(L8<8, IF(L8<4,1,-1), 0) -> -1 | T8: =VLOOKUP(main!$L$1,table!$B$3:$F$66,N8+2,FALSE)*Q8 -> 127 | U8: =VLOOKUP(main!$L$1,table!$B$3:$F$66,O8+2,FALSE)*R8 -> -118 | V8: =VLOOKUP(main!$L$1,table!$B$3:$F$66,P8+2,FALSE)*S8 -> -52
A9: =2*(B9+1) -> 14 | B9: 6 | C9: =INT(((SIN(2*PI()*C$67/24)+SIN(6*PI()*C$67/24)*main!$B$1)*value!$J$1*$A9)+0.5) -> 6 | D9: =INT(((SIN(2*PI()*D$67/24)+SIN(6*PI()*D$67/24)*main!$B$1)*value!$J$1*$A9)+0.5) -> 10 | E9: =INT(((SIN(2*PI()*E$67/24)+SIN(6*PI()*E$67/24)*main!$B$1)*value!$J$1*$A9)+0.5) -> 13 | F9: =INT(((SIN(2*PI()*F$67/24)+SIN(6*PI()*F$67/24)*main!$B$1)*value!$J$1*$A9)+0.5) -> 14 | I9: 6 | J9: 3 | K9: 7 | L9: 8 | N9: =MOD(J9,4) -> 3 | O9: =MOD(K9,4) -> 3 | P9: =MOD(L9,4) -> 0 | Q9: =IF(J9<8, IF(J9<4,1,-1), 0) -> 1 | R9: =IF(K9<8, IF(K9<4,1,-1), 0) -> -1 | S9: =IF(L9<8, IF(L9<4,1,-1), 0) -> 0 | T9: =VLOOKUP(main!$L$1,table!$B$3:$F$66,N9+2,FALSE)*Q9 -> 127 | U9: =VLOOKUP(main!$L$1,table!$B$3:$F$66,O9+2,FALSE)*R9 -> -127 | V9: =VLOOKUP(main!$L$1,table!$B$3:$F$66,P9+2,FALSE)*S9 -> 0
A10: =2*(B10+1) -> 16 | B10: 7 | C10: =INT(((SIN(2*PI()*C$67/24)+SIN(6*PI()*C$67/24)*main!$B$1)*value!$J$1*$A10)+0.5) -> 7 | D10: =INT(((SIN(2*PI()*D$67/24)+SIN(6*PI()*D$67/24)*main!$B$1)*value!$J$1*$A10)+0.5) -> 12 | E10: =INT(((SIN(2*PI()*E$67/24)+SIN(6*PI()*E$67/24)*main!$B$1)*value!$J$1*$A10)+0.5) -> 15 | F10: =INT(((SIN(2*PI()*F$67/24)+SIN(6*PI()*F$67/24)*main!$B$1)*value!$J$1*$A10)+0.5) -> 16 | I10: 7 | J10: 2 | K10: 7 | L10: 0 | N10: =MOD(J10,4) -> 2 | O10: =MOD(K10,4) -> 3 | P10: =MOD(L10,4) -> 0 | Q10: =IF(J10<8, IF(J10<4,1,-1), 0) -> 1 | R10: =IF(K10<8, IF(K10<4,1,-1), 0) -> -1 | S10: =IF(L10<8, IF(L10<4,1,-1), 0) -> 1 | T10: =VLOOKUP(main!$L$1,table!$B$3:$F$66,N10+2,FALSE)*Q10 -> 118 | U10: =VLOOKUP(main!$L$1,table!$B$3:$F$66,O10+2,FALSE)*R10 -> -127 | V10: =VLOOKUP(main!$L$1,table!$B$3:$F$66,P10+2,FALSE)*S10 -> 52
A11: =2*(B11+1) -> 18 | B11: 8 | C11: =INT(((SIN(2*PI()*C$67/24)+SIN(6*PI()*C$67/24)*main!$B$1)*value!$J$1*$A11)+0.5) -> 7 | D11: =INT(((SIN(2*PI()*D$67/24)+SIN(6*PI()*D$67/24)*main!$B$1)*value!$J$1*$A11)+0.5) -> 13 | E11: =INT(((SIN(2*PI()*E$67/24)+SIN(6*PI()*E$67/24)*main!$B$1)*value!$J$1*$A11)+0.5) -> 17 | F11: =INT(((SIN(2*PI()*F$67/24)+SIN(6*PI()*F$67/24)*main!$B$1)*value!$J$1*$A11)+0.5) -> 18 | I11: 8 | J11: 1 | K11: 7 | L11: 1 | N11: =MOD(J11,4) -> 1 | O11: =MOD(K11,4) -> 3 | P11: =MOD(L11,4) -> 1 | Q11: =IF(J11<8, IF(J11<4,1,-1), 0) -> 1 | R11: =IF(K11<8, IF(K11<4,1,-1), 0) -> -1 | S11: =IF(L11<8, IF(L11<4,1,-1), 0) -> 1 | T11: =VLOOKUP(main!$L$1,table!$B$3:$F$66,N11+2,FALSE)*Q11 -> 93 | U11: =VLOOKUP(main!$L$1,table!$B$3:$F$66,O11+2,FALSE)*R11 -> -127 | V11: =VLOOKUP(main!$L$1,table!$B$3:$F$66,P11+2,FALSE)*S11 -> 93
A12: =2*(B12+1) -> 20 | B12: 9 | C12: =INT(((SIN(2*PI()*C$67/24)+SIN(6*PI()*C$67/24)*main!$B$1)*value!$J$1*$A12)+0.5) -> 8 | D12: =INT(((SIN(2*PI()*D$67/24)+SIN(6*PI()*D$67/24)*main!$B$1)*value!$J$1*$A12)+0.5) -> 15 | E12: =INT(((SIN(2*PI()*E$67/24)+SIN(6*PI()*E$67/24)*main!$B$1)*value!$J$1*$A12)+0.5) -> 18 | F12: =INT(((SIN(2*PI()*F$67/24)+SIN(6*PI()*F$67/24)*main!$B$1)*value!$J$1*$A12)+0.5) -> 20 | I12: 9 | J12: 0 | K12: 7 | L12: 2 | N12: =MOD(J12,4) -> 0 | O12: =MOD(K12,4) -> 3 | P12: =MOD(L12,4) -> 2 | Q12: =IF(J12<8, IF(J12<4,1,-1), 0) -> 1 | R12: =IF(K12<8, IF(K12<4,1,-1), 0) -> -1 | S12: =IF(L12<8, IF(L12<4,1,-1), 0) -> 1 | T12: =VLOOKUP(main!$L$1,table!$B$3:$F$66,N12+2,FALSE)*Q12 -> 52 | U12: =VLOOKUP(main!$L$1,table!$B$3:$F$66,O12+2,FALSE)*R12 -> -127 | V12: =VLOOKUP(main!$L$1,table!$B$3:$F$66,P12+2,FALSE)*S12 -> 118
A13: =2*(B13+1) -> 22 | B13: 10 | C13: =INT(((SIN(2*PI()*C$67/24)+SIN(6*PI()*C$67/24)*main!$B$1)*value!$J$1*$A13)+0.5) -> 9 | D13: =INT(((SIN(2*PI()*D$67/24)+SIN(6*PI()*D$67/24)*main!$B$1)*value!$J$1*$A13)+0.5) -> 16 | E13: =INT(((SIN(2*PI()*E$67/24)+SIN(6*PI()*E$67/24)*main!$B$1)*value!$J$1*$A13)+0.5) -> 20 | F13: =INT(((SIN(2*PI()*F$67/24)+SIN(6*PI()*F$67/24)*main!$B$1)*value!$J$1*$A13)+0.5) -> 22 | I13: 10 | J13: 8 | K13: 7 | L13: 3 | N13: =MOD(J13,4) -> 0 | O13: =MOD(K13,4) -> 3 | P13: =MOD(L13,4) -> 3 | Q13: =IF(J13<8, IF(J13<4,1,-1), 0) -> 0 | R13: =IF(K13<8, IF(K13<4,1,-1), 0) -> -1 | S13: =IF(L13<8, IF(L13<4,1,-1), 0) -> 1 | T13: =VLOOKUP(main!$L$1,table!$B$3:$F$66,N13+2,FALSE)*Q13 -> 0 | U13: =VLOOKUP(main!$L$1,table!$B$3:$F$66,O13+2,FALSE)*R13 -> -127 | V13: =VLOOKUP(main!$L$1,table!$B$3:$F$66,P13+2,FALSE)*S13 -> 127
A14: =2*(B14+1) -> 24 | B14: 11 | C14: =INT(((SIN(2*PI()*C$67/24)+SIN(6*PI()*C$67/24)*main!$B$1)*value!$J$1*$A14)+0.5) -> 10 | D14: =INT(((SIN(2*PI()*D$67/24)+SIN(6*PI()*D$67/24)*main!$B$1)*value!$J$1*$A14)+0.5) -> 18 | E14: =INT(((SIN(2*PI()*E$67/24)+SIN(6*PI()*E$67/24)*main!$B$1)*value!$J$1*$A14)+0.5) -> 22 | F14: =INT(((SIN(2*PI()*F$67/24)+SIN(6*PI()*F$67/24)*main!$B$1)*value!$J$1*$A14)+0.5) -> 24 | I14: 11 | J14: 4 | K14: 6 | L14: 3 | N14: =MOD(J14,4) -> 0 | O14: =MOD(K14,4) -> 2 | P14: =MOD(L14,4) -> 3 | Q14: =IF(J14<8, IF(J14<4,1,-1), 0) -> -1 | R14: =IF(K14<8, IF(K14<4,1,-1), 0) -> -1 | S14: =IF(L14<8, IF(L14<4,1,-1), 0) -> 1 | T14: =VLOOKUP(main!$L$1,table!$B$3:$F$66,N14+2,FALSE)*Q14 -> -52 | U14: =VLOOKUP(main!$L$1,table!$B$3:$F$66,O14+2,FALSE)*R14 -> -118 | V14: =VLOOKUP(main!$L$1,table!$B$3:$F$66,P14+2,FALSE)*S14 -> 127
A15: =2*(B15+1) -> 26 | B15: 12 | C15: =INT(((SIN(2*PI()*C$67/24)+SIN(6*PI()*C$67/24)*main!$B$1)*value!$J$1*$A15)+0.5) -> 11 | D15: =INT(((SIN(2*PI()*D$67/24)+SIN(6*PI()*D$67/24)*main!$B$1)*value!$J$1*$A15)+0.5) -> 19 | E15: =INT(((SIN(2*PI()*E$67/24)+SIN(6*PI()*E$67/24)*main!$B$1)*value!$J$1*$A15)+0.5) -> 24 | F15: =INT(((SIN(2*PI()*F$67/24)+SIN(6*PI()*F$67/24)*main!$B$1)*value!$J$1*$A15)+0.5) -> 26 | I15: 12 | J15: 5 | K15: 5 | L15: 3 | N15: =MOD(J15,4) -> 1 | O15: =MOD(K15,4) -> 1 | P15: =MOD(L15,4) -> 3 | Q15: =IF(J15<8, IF(J15<4,1,-1), 0) -> -1 | R15: =IF(K15<8, IF(K15<4,1,-1), 0) -> -1 | S15: =IF(L15<8, IF(L15<4,1,-1), 0) -> 1 | T15: =VLOOKUP(main!$L$1,table!$B$3:$F$66,N15+2,FALSE)*Q15 -> -93 | U15: =VLOOKUP(main!$L$1,table!$B$3:$F$66,O15+2,FALSE)*R15 -> -93 | V15: =VLOOKUP(main!$L$1,table!$B$3:$F$66,P15+2,FALSE)*S15 -> 127
A16: =2*(B16+1) -> 28 | B16: 13 | C16: =INT(((SIN(2*PI()*C$67/24)+SIN(6*PI()*C$67/24)*main!$B$1)*value!$J$1*$A16)+0.5) -> 11 | D16: =INT(((SIN(2*PI()*D$67/24)+SIN(6*PI()*D$67/24)*main!$B$1)*value!$J$1*$A16)+0.5) -> 20 | E16: =INT(((SIN(2*PI()*E$67/24)+SIN(6*PI()*E$67/24)*main!$B$1)*value!$J$1*$A16)+0.5) -> 26 | F16: =INT(((SIN(2*PI()*F$67/24)+SIN(6*PI()*F$67/24)*main!$B$1)*value!$J$1*$A16)+0.5) -> 28 | I16: 13 | J16: 6 | K16: 4 | L16: 3 | N16: =MOD(J16,4) -> 2 | O16: =MOD(K16,4) -> 0 | P16: =MOD(L16,4) -> 3 | Q16: =IF(J16<8, IF(J16<4,1,-1), 0) -> -1 | R16: =IF(K16<8, IF(K16<4,1,-1), 0) -> -1 | S16: =IF(L16<8, IF(L16<4,1,-1), 0) -> 1 | T16: =VLOOKUP(main!$L$1,table!$B$3:$F$66,N16+2,FALSE)*Q16 -> -118 | U16: =VLOOKUP(main!$L$1,table!$B$3:$F$66,O16+2,FALSE)*R16 -> -52 | V16: =VLOOKUP(main!$L$1,table!$B$3:$F$66,P16+2,FALSE)*S16 -> 127
A17: =2*(B17+1) -> 30 | B17: 14 | C17: =INT(((SIN(2*PI()*C$67/24)+SIN(6*PI()*C$67/24)*main!$B$1)*value!$J$1*$A17)+0.5) -> 12 | D17: =INT(((SIN(2*PI()*D$67/24)+SIN(6*PI()*D$67/24)*main!$B$1)*value!$J$1*$A17)+0.5) -> 22 | E17: =INT(((SIN(2*PI()*E$67/24)+SIN(6*PI()*E$67/24)*main!$B$1)*value!$J$1*$A17)+0.5) -> 28 | F17: =INT(((SIN(2*PI()*F$67/24)+SIN(6*PI()*F$67/24)*main!$B$1)*value!$J$1*$A17)+0.5) -> 30 | I17: 14 | J17: 7 | K17: 8 | L17: 3 | N17: =MOD(J17,4) -> 3 | O17: =MOD(K17,4) -> 0 | P17: =MOD(L17,4) -> 3 | Q17: =IF(J17<8, IF(J17<4,1,-1), 0) -> -1 | R17: =IF(K17<8, IF(K17<4,1,-1), 0) -> 0 | S17: =IF(L17<8, IF(L17<4,1,-1), 0) -> 1 | T17: =VLOOKUP(main!$L$1,table!$B$3:$F$66,N17+2,FALSE)*Q17 -> -127 | U17: =VLOOKUP(main!$L$1,table!$B$3:$F$66,O17+2,FALSE)*R17 -> 0 | V17: =VLOOKUP(main!$L$1,table!$B$3:$F$66,P17+2,FALSE)*S17 -> 127
... A26: =2*(B26+1) -> 48 | B26: 23 | C26: =INT(((SIN(2*PI()*C$67/24)+SIN(6*PI()*C$67/24)*main!$B$1)*value!$J$1*$A26)+0.5) -> 20 | D26: =INT(((SIN(2*PI()*D$67/24)+SIN(6*PI()*D$67/24)*main!$B$1)*value!$J$1*$A26)+0.5) -> 35 | E26: =INT(((SIN(2*PI()*E$67/24)+SIN(6*PI()*E$67/24)*main!$B$1)*value!$J$1*$A26)+0.5) -> 44 | F26: =INT(((SIN(2*PI()*F$67/24)+SIN(6*PI()*F$67/24)*main!$B$1)*value!$J$1*$A26)+0.5) -> 48 | I26: 23 | J26: 0 | K26: 2 | L26: 7 | N26: =MOD(J26,4) -> 0 | O26: =MOD(K26,4) -> 2 | P26: =MOD(L26,4) -> 3 | Q26: =IF(J26<8, IF(J26<4,1,-1), 0) -> 1 | R26: =IF(K26<8, IF(K26<4,1,-1), 0) -> 1 | S26: =IF(L26<8, IF(L26<4,1,-1), 0) -> -1 | T26: =VLOOKUP(main!$L$1,table!$B$3:$F$66,N26+2,FALSE)*Q26 -> 52 | U26: =VLOOKUP(main!$L$1,table!$B$3:$F$66,O26+2,FALSE)*R26 -> 118 | V26: =VLOOKUP(main!$L$1,table!$B$3:$F$66,P26+2,FALSE)*S26 -> -127
A27: =2*(B27+1) -> 50 | B27: 24 | C27: =INT(((SIN(2*PI()*C$67/24)+SIN(6*PI()*C$67/24)*main!$B$1)*value!$J$1*$A27)+0.5) -> 20 | D27: =INT(((SIN(2*PI()*D$67/24)+SIN(6*PI()*D$67/24)*main!$B$1)*value!$J$1*$A27)+0.5) -> 36 | E27: =INT(((SIN(2*PI()*E$67/24)+SIN(6*PI()*E$67/24)*main!$B$1)*value!$J$1*$A27)+0.5) -> 46 | F27: =INT(((SIN(2*PI()*F$67/24)+SIN(6*PI()*F$67/24)*main!$B$1)*value!$J$1*$A27)+0.5) -> 50
A28: =2*(B28+1) -> 52 | B28: 25 | C28: =INT(((SIN(2*PI()*C$67/24)+SIN(6*PI()*C$67/24)*main!$B$1)*value!$J$1*$A28)+0.5) -> 21 | D28: =INT(((SIN(2*PI()*D$67/24)+SIN(6*PI()*D$67/24)*main!$B$1)*value!$J$1*$A28)+0.5) -> 38 | E28: =INT(((SIN(2*PI()*E$67/24)+SIN(6*PI()*E$67/24)*main!$B$1)*value!$J$1*$A28)+0.5) -> 48 | F28: =INT(((SIN(2*PI()*F$67/24)+SIN(6*PI()*F$67/24)*main!$B$1)*value!$J$1*$A28)+0.5) -> 52
A29: =2*(B29+1) -> 54 | B29: 26 | C29: =INT(((SIN(2*PI()*C$67/24)+SIN(6*PI()*C$67/24)*main!$B$1)*value!$J$1*$A29)+0.5) -> 22 | D29: =INT(((SIN(2*PI()*D$67/24)+SIN(6*PI()*D$67/24)*main!$B$1)*value!$J$1*$A29)+0.5) -> 39 | E29: =INT(((SIN(2*PI()*E$67/24)+SIN(6*PI()*E$67/24)*main!$B$1)*value!$J$1*$A29)+0.5) -> 50 | F29: =INT(((SIN(2*PI()*F$67/24)+SIN(6*PI()*F$67/24)*main!$B$1)*value!$J$1*$A29)+0.5) -> 54
A30: =2*(B30+1) -> 56 | B30: 27 | C30: =INT(((SIN(2*PI()*C$67/24)+SIN(6*PI()*C$67/24)*main!$B$1)*value!$J$1*$A30)+0.5) -> 23 | D30: =INT(((SIN(2*PI()*D$67/24)+SIN(6*PI()*D$67/24)*main!$B$1)*value!$J$1*$A30)+0.5) -> 41 | E30: =INT(((SIN(2*PI()*E$67/24)+SIN(6*PI()*E$67/24)*main!$B$1)*value!$J$1*$A30)+0.5) -> 52 | F30: =INT(((SIN(2*PI()*F$67/24)+SIN(6*PI()*F$67/24)*main!$B$1)*value!$J$1*$A30)+0.5) -> 56
A31: =2*(B31+1) -> 58 | B31: 28 | C31: =INT(((SIN(2*PI()*C$67/24)+SIN(6*PI()*C$67/24)*main!$B$1)*value!$J$1*$A31)+0.5) -> 24 | D31: =INT(((SIN(2*PI()*D$67/24)+SIN(6*PI()*D$67/24)*main!$B$1)*value!$J$1*$A31)+0.5) -> 42 | E31: =INT(((SIN(2*PI()*E$67/24)+SIN(6*PI()*E$67/24)*main!$B$1)*value!$J$1*$A31)+0.5) -> 53 | F31: =INT(((SIN(2*PI()*F$67/24)+SIN(6*PI()*F$67/24)*main!$B$1)*value!$J$1*$A31)+0.5) -> 58
A32: =2*(B32+1) -> 60 | B32: 29 | C32: =INT(((SIN(2*PI()*C$67/24)+SIN(6*PI()*C$67/24)*main!$B$1)*value!$J$1*$A32)+0.5) -> 24 | D32: =INT(((SIN(2*PI()*D$67/24)+SIN(6*PI()*D$67/24)*main!$B$1)*value!$J$1*$A32)+0.5) -> 44 | E32: =INT(((SIN(2*PI()*E$67/24)+SIN(6*PI()*E$67/24)*main!$B$1)*value!$J$1*$A32)+0.5) -> 55 | F32: =INT(((SIN(2*PI()*F$67/24)+SIN(6*PI()*F$67/24)*main!$B$1)*value!$J$1*$A32)+0.5) -> 60
A33: =2*(B33+1) -> 62 | B33: 30 | C33: =INT(((SIN(2*PI()*C$67/24)+SIN(6*PI()*C$67/24)*main!$B$1)*value!$J$1*$A33)+0.5) -> 25 | D33: =INT(((SIN(2*PI()*D$67/24)+SIN(6*PI()*D$67/24)*main!$B$1)*value!$J$1*$A33)+0.5) -> 45 | E33: =INT(((SIN(2*PI()*E$67/24)+SIN(6*PI()*E$67/24)*main!$B$1)*value!$J$1*$A33)+0.5) -> 57 | F33: =INT(((SIN(2*PI()*F$67/24)+SIN(6*PI()*F$67/24)*main!$B$1)*value!$J$1*$A33)+0.5) -> 62
A34: =2*(B34+1) -> 64 | B34: 31 | C34: =INT(((SIN(2*PI()*C$67/24)+SIN(6*PI()*C$67/24)*main!$B$1)*value!$J$1*$A34)+0.5) -> 26 | D34: =INT(((SIN(2*PI()*D$67/24)+SIN(6*PI()*D$67/24)*main!$B$1)*value!$J$1*$A34)+0.5) -> 47 | E34: =INT(((SIN(2*PI()*E$67/24)+SIN(6*PI()*E$67/24)*main!$B$1)*value!$J$1*$A34)+0.5) -> 59 | F34: =INT(((SIN(2*PI()*F$67/24)+SIN(6*PI()*F$67/24)*main!$B$1)*value!$J$1*$A34)+0.5) -> 64
A35: =2*(B35+1) -> 66 | B35: 32 | C35: =INT(((SIN(2*PI()*C$67/24)+SIN(6*PI()*C$67/24)*main!$B$1)*value!$J$1*$A35)+0.5) -> 27 | D35: =INT(((SIN(2*PI()*D$67/24)+SIN(6*PI()*D$67/24)*main!$B$1)*value!$J$1*$A35)+0.5) -> 48 | E35: =INT(((SIN(2*PI()*E$67/24)+SIN(6*PI()*E$67/24)*main!$B$1)*value!$J$1*$A35)+0.5) -> 61 | F35: =INT(((SIN(2*PI()*F$67/24)+SIN(6*PI()*F$67/24)*main!$B$1)*value!$J$1*$A35)+0.5) -> 66
A36: =2*(B36+1) -> 68 | B36: 33 | C36: =INT(((SIN(2*PI()*C$67/24)+SIN(6*PI()*C$67/24)*main!$B$1)*value!$J$1*$A36)+0.5) -> 28 | D36: =INT(((SIN(2*PI()*D$67/24)+SIN(6*PI()*D$67/24)*main!$B$1)*value!$J$1*$A36)+0.5) -> 50 | E36: =INT(((SIN(2*PI()*E$67/24)+SIN(6*PI()*E$67/24)*main!$B$1)*value!$J$1*$A36)+0.5) -> 63 | F36: =INT(((SIN(2*PI()*F$67/24)+SIN(6*PI()*F$67/24)*main!$B$1)*value!$J$1*$A36)+0.5) -> 68
A37: =2*(B37+1) -> 70 | B37: 34 | C37: =INT(((SIN(2*PI()*C$67/24)+SIN(6*PI()*C$67/24)*main!$B$1)*value!$J$1*$A37)+0.5) -> 28 | D37: =INT(((SIN(2*PI()*D$67/24)+SIN(6*PI()*D$67/24)*main!$B$1)*value!$J$1*$A37)+0.5) -> 51 | E37: =INT(((SIN(2*PI()*E$67/24)+SIN(6*PI()*E$67/24)*main!$B$1)*value!$J$1*$A37)+0.5) -> 65 | F37: =INT(((SIN(2*PI()*F$67/24)+SIN(6*PI()*F$67/24)*main!$B$1)*value!$J$1*$A37)+0.5) -> 70
A38: =2*(B38+1) -> 72 | B38: 35 | C38: =INT(((SIN(2*PI()*C$67/24)+SIN(6*PI()*C$67/24)*main!$B$1)*value!$J$1*$A38)+0.5) -> 29 | D38: =INT(((SIN(2*PI()*D$67/24)+SIN(6*PI()*D$67/24)*main!$B$1)*value!$J$1*$A38)+0.5) -> 53 | E38: =INT(((SIN(2*PI()*E$67/24)+SIN(6*PI()*E$67/24)*main!$B$1)*value!$J$1*$A38)+0.5) -> 66 | F38: =INT(((SIN(2*PI()*F$67/24)+SIN(6*PI()*F$67/24)*main!$B$1)*value!$J$1*$A38)+0.5) -> 72
... A66: =2*(B66+1) -> 128 | B66: 63 | C66: =INT(((SIN(2*PI()*C$67/24)+SIN(6*PI()*C$67/24)*main!$B$1)*value!$J$1*$A66)+0.5) -> 52 | D66: =INT(((SIN(2*PI()*D$67/24)+SIN(6*PI()*D$67/24)*main!$B$1)*value!$J$1*$A66)+0.5) -> 93 | E66: =INT(((SIN(2*PI()*E$67/24)+SIN(6*PI()*E$67/24)*main!$B$1)*value!$J$1*$A66)+0.5) -> 118 | F66: =INT(((SIN(2*PI()*F$67/24)+SIN(6*PI()*F$67/24)*main!$B$1)*value!$J$1*$A66)+0.5) -> 127
C67: 1 | D67: 2 | E67: 3 | F67: 4

Sheet value
B1: Z相 | C1: U相 | D1: V相 | E1: A = U相+Z相 | F1: B = V相+Z相 | G1: A | H1: B | I1: A - B | J1: =1/J2 -> 1.1488094 | M1: deg | N1: step | O1: A | P1: B | Q1: A - B | R1: 振幅スペクトル | T1: =0.25/(main!L1+1) -> 0.00390625
A2: 0 | B2: =SIN(6*PI()*A2/24)*main!$B$1 -> 0 | C2: =SIN(2*PI()*A2/24) -> 0 | D2: =SIN(2*PI()*A2/24+2*PI()/3) -> 0.8660254 | E2: =C2+$B2 -> 0 | F2: =D2+$B2 -> 0.8660254 | G2: =E2*$J$1 -> 0 | H2: =F2*$J$1 -> 0.99489813 | I2: =G2-H2 -> -0.99489813 | J2: =MAX(E2:E25) -> 0.87046641 | L2: 0 | M2: =INT(MOD(main!$T$1*L2,24)*360/24) -> 0 | N2: =MOD(INT(M2*24/360),24) -> 0 | O2: =VLOOKUP($N2,table!$I$3:$V$26,12,FALSE)*$T$1 -> 0.36328125 | P2: =VLOOKUP($N2,table!$I$3:$V$26,13,FALSE)*$T$1 -> 0.36328125 | Q2: =O2-P2 -> 0 | R2: =IF(dft_cos!B$1<1/dft_cos!$A$3, 20*LOG10(1/dft_cos!$A$3),20*LOG10(dft_cos!B$1)) -> -93.9794
A3: 1 | B3: =SIN(6*PI()*A3/24)*main!$B$1 -> 0.095459415 | C3: =SIN(2*PI()*A3/24) -> 0.25881905 | D3: =SIN(2*PI()*A3/24+2*PI()/3) -> 0.70710678 | E3: =C3+$B3 -> 0.35427846 | F3: =D3+$B3 -> 0.8025662 | G3: =E3*$J$1 -> 0.40699843 | H3: =F3*$J$1 -> 0.9219956 | I3: =G3-H3 -> -0.51499717 | L3: 1 | M3: =INT(MOD(main!$T$1*L3,24)*360/24) -> 0 | N3: =MOD(INT(M3*24/360),24) -> 0 | O3: =VLOOKUP($N3,table!$I$3:$V$26,12,FALSE)*$T$1 -> 0.36328125 | P3: =VLOOKUP($N3,table!$I$3:$V$26,13,FALSE)*$T$1 -> 0.36328125 | Q3: =O3-P3 -> 0 | R3: =IF(dft_cos!C$1<1/dft_cos!$A$3, 20*LOG10(1/dft_cos!$A$3),20*LOG10(dft_cos!C$1)) -> -0.10046978
A4: 2 | B4: =SIN(6*PI()*A4/24)*main!$B$1 -> 0.135 | C4: =SIN(2*PI()*A4/24) -> 0.5 | D4: =SIN(2*PI()*A4/24+2*PI()/3) -> 0.5 | E4: =C4+$B4 -> 0.635 | F4: =D4+$B4 -> 0.635 | G4: =E4*$J$1 -> 0.72949397 | H4: =F4*$J$1 -> 0.72949397 | I4: =G4-H4 -> 0 | L4: 2 | M4: =INT(MOD(main!$T$1*L4,24)*360/24) -> 1 | N4: =MOD(INT(M4*24/360),24) -> 0 | O4: =VLOOKUP($N4,table!$I$3:$V$26,12,FALSE)*$T$1 -> 0.36328125 | P4: =VLOOKUP($N4,table!$I$3:$V$26,13,FALSE)*$T$1 -> 0.36328125 | Q4: =O4-P4 -> 0 | R4: =IF(dft_cos!D$1<1/dft_cos!$A$3, 20*LOG10(1/dft_cos!$A$3),20*LOG10(dft_cos!D$1)) -> -93.9794
A5: 3 | B5: =SIN(6*PI()*A5/24)*main!$B$1 -> 0.095459415 | C5: =SIN(2*PI()*A5/24) -> 0.70710678 | D5: =SIN(2*PI()*A5/24+2*PI()/3) -> 0.25881905 | E5: =C5+$B5 -> 0.8025662 | F5: =D5+$B5 -> 0.35427846 | G5: =E5*$J$1 -> 0.9219956 | H5: =F5*$J$1 -> 0.40699843 | I5: =G5-H5 -> 0.51499717 | L5: 3 | M5: =INT(MOD(main!$T$1*L5,24)*360/24) -> 2 | N5: =MOD(INT(M5*24/360),24) -> 0 | O5: =VLOOKUP($N5,table!$I$3:$V$26,12,FALSE)*$T$1 -> 0.36328125 | P5: =VLOOKUP($N5,table!$I$3:$V$26,13,FALSE)*$T$1 -> 0.36328125 | Q5: =O5-P5 -> 0 | R5: =IF(dft_cos!E$1<1/dft_cos!$A$3, 20*LOG10(1/dft_cos!$A$3),20*LOG10(dft_cos!E$1)) -> -93.9794
A6: 4 | B6: =SIN(6*PI()*A6/24)*main!$B$1 -> 1.6539504e-17 | C6: =SIN(2*PI()*A6/24) -> 0.8660254 | D6: =SIN(2*PI()*A6/24+2*PI()/3) -> 1.2251485e-16 | E6: =C6+$B6 -> 0.8660254 | F6: =D6+$B6 -> 1.3905435e-16 | G6: =E6*$J$1 -> 0.99489813 | H6: =F6*$J$1 -> 1.5974694e-16 | I6: =G6-H6 -> 0.99489813 | L6: 4 | M6: =INT(MOD(main!$T$1*L6,24)*360/24) -> 3 | N6: =MOD(INT(M6*24/360),24) -> 0 | O6: =VLOOKUP($N6,table!$I$3:$V$26,12,FALSE)*$T$1 -> 0.36328125 | P6: =VLOOKUP($N6,table!$I$3:$V$26,13,FALSE)*$T$1 -> 0.36328125 | Q6: =O6-P6 -> 0 | R6: =IF(dft_cos!F$1<1/dft_cos!$A$3, 20*LOG10(1/dft_cos!$A$3),20*LOG10(dft_cos!F$1)) -> -93.9794
A7: 5 | B7: =SIN(6*PI()*A7/24)*main!$B$1 -> -0.095459415 | C7: =SIN(2*PI()*A7/24) -> 0.96592583 | D7: =SIN(2*PI()*A7/24+2*PI()/3) -> -0.25881905 | E7: =C7+$B7 -> 0.87046641 | F7: =D7+$B7 -> -0.35427846 | G7: =E7*$J$1 -> 1 | H7: =F7*$J$1 -> -0.40699843 | I7: =G7-H7 -> 1.4069984 | L7: 5 | M7: =INT(MOD(main!$T$1*L7,24)*360/24) -> 4 | N7: =MOD(INT(M7*24/360),24) -> 0 | O7: =VLOOKUP($N7,table!$I$3:$V$26,12,FALSE)*$T$1 -> 0.36328125 | P7: =VLOOKUP($N7,table!$I$3:$V$26,13,FALSE)*$T$1 -> 0.36328125 | Q7: =O7-P7 -> 0 | R7: =IF(dft_cos!G$1<1/dft_cos!$A$3, 20*LOG10(1/dft_cos!$A$3),20*LOG10(dft_cos!G$1)) -> -63.307404
A8: 6 | B8: =SIN(6*PI()*A8/24)*main!$B$1 -> -0.135 | C8: =SIN(2*PI()*A8/24) -> 1 | D8: =SIN(2*PI()*A8/24+2*PI()/3) -> -0.5 | E8: =C8+$B8 -> 0.865 | F8: =D8+$B8 -> -0.635 | G8: =E8*$J$1 -> 0.99372014 | H8: =F8*$J$1 -> -0.72949397 | I8: =G8-H8 -> 1.7232141 | L8: 6 | M8: =INT(MOD(main!$T$1*L8,24)*360/24) -> 5 | N8: =MOD(INT(M8*24/360),24) -> 0 | O8: =VLOOKUP($N8,table!$I$3:$V$26,12,FALSE)*$T$1 -> 0.36328125 | P8: =VLOOKUP($N8,table!$I$3:$V$26,13,FALSE)*$T$1 -> 0.36328125 | Q8: =O8-P8 -> 0 | R8: =IF(dft_cos!H$1<1/dft_cos!$A$3, 20*LOG10(1/dft_cos!$A$3),20*LOG10(dft_cos!H$1)) -> -93.9794
A9: 7 | B9: =SIN(6*PI()*A9/24)*main!$B$1 -> -0.095459415 | C9: =SIN(2*PI()*A9/24) -> 0.96592583 | D9: =SIN(2*PI()*A9/24+2*PI()/3) -> -0.70710678 | E9: =C9+$B9 -> 0.87046641 | F9: =D9+$B9 -> -0.8025662 | G9: =E9*$J$1 -> 1 | H9: =F9*$J$1 -> -0.9219956 | I9: =G9-H9 -> 1.9219956 | L9: 7 | M9: =INT(MOD(main!$T$1*L9,24)*360/24) -> 6 | N9: =MOD(INT(M9*24/360),24) -> 0 | O9: =VLOOKUP($N9,table!$I$3:$V$26,12,FALSE)*$T$1 -> 0.36328125 | P9: =VLOOKUP($N9,table!$I$3:$V$26,13,FALSE)*$T$1 -> 0.36328125 | Q9: =O9-P9 -> 0 | R9: =IF(dft_cos!I$1<1/dft_cos!$A$3, 20*LOG10(1/dft_cos!$A$3),20*LOG10(dft_cos!I$1)) -> -63.172906
A10: 8 | B10: =SIN(6*PI()*A10/24)*main!$B$1 -> -3.3079008e-17 | C10: =SIN(2*PI()*A10/24) -> 0.8660254 | D10: =SIN(2*PI()*A10/24+2*PI()/3) -> -0.8660254 | E10: =C10+$B10 -> 0.8660254 | F10: =D10+$B10 -> -0.8660254 | G10: =E10*$J$1 -> 0.99489813 | H10: =F10*$J$1 -> -0.99489813 | I10: =G10-H10 -> 1.9897963 | L10: 8 | M10: =INT(MOD(main!$T$1*L10,24)*360/24) -> 7 | N10: =MOD(INT(M10*24/360),24) -> 0 | O10: =VLOOKUP($N10,table!$I$3:$V$26,12,FALSE)*$T$1 -> 0.36328125 | P10: =VLOOKUP($N10,table!$I$3:$V$26,13,FALSE)*$T$1 -> 0.36328125 | Q10: =O10-P10 -> 0 | R10: =IF(dft_cos!J$1<1/dft_cos!$A$3, 20*LOG10(1/dft_cos!$A$3),20*LOG10(dft_cos!J$1)) -> -93.9794
A11: 9 | B11: =SIN(6*PI()*A11/24)*main!$B$1 -> 0.095459415 | C11: =SIN(2*PI()*A11/24) -> 0.70710678 | D11: =SIN(2*PI()*A11/24+2*PI()/3) -> -0.96592583 | E11: =C11+$B11 -> 0.8025662 | F11: =D11+$B11 -> -0.87046641 | G11: =E11*$J$1 -> 0.9219956 | H11: =F11*$J$1 -> -1 | I11: =G11-H11 -> 1.9219956 | L11: 9 | M11: =INT(MOD(main!$T$1*L11,24)*360/24) -> 8 | N11: =MOD(INT(M11*24/360),24) -> 0 | O11: =VLOOKUP($N11,table!$I$3:$V$26,12,FALSE)*$T$1 -> 0.36328125 | P11: =VLOOKUP($N11,table!$I$3:$V$26,13,FALSE)*$T$1 -> 0.36328125 | Q11: =O11-P11 -> 0 | R11: =IF(dft_cos!K$1<1/dft_cos!$A$3, 20*LOG10(1/dft_cos!$A$3),20*LOG10(dft_cos!K$1)) -> -93.9794
A12: 10 | B12: =SIN(6*PI()*A12/24)*main!$B$1 -> 0.135 | C12: =SIN(2*PI()*A12/24) -> 0.5 | D12: =SIN(2*PI()*A12/24+2*PI()/3) -> -1 | E12: =C12+$B12 -> 0.635 | F12: =D12+$B12 -> -0.865 | G12: =E12*$J$1 -> 0.72949397 | H12: =F12*$J$1 -> -0.99372014 | I12: =G12-H12 -> 1.7232141 | L12: 10 | M12: =INT(MOD(main!$T$1*L12,24)*360/24) -> 9 | N12: =MOD(INT(M12*24/360),24) -> 0 | O12: =VLOOKUP($N12,table!$I$3:$V$26,12,FALSE)*$T$1 -> 0.36328125 | P12: =VLOOKUP($N12,table!$I$3:$V$26,13,FALSE)*$T$1 -> 0.36328125 | Q12: =O12-P12 -> 0 | R12: =IF(dft_cos!L$1<1/dft_cos!$A$3, 20*LOG10(1/dft_cos!$A$3),20*LOG10(dft_cos!L$1)) -> -93.9794
A13: 11 | B13: =SIN(6*PI()*A13/24)*main!$B$1 -> 0.095459415 | C13: =SIN(2*PI()*A13/24) -> 0.25881905 | D13: =SIN(2*PI()*A13/24+2*PI()/3) -> -0.96592583 | E13: =C13+$B13 -> 0.35427846 | F13: =D13+$B13 -> -0.87046641 | G13: =E13*$J$1 -> 0.40699843 | H13: =F13*$J$1 -> -1 | I13: =G13-H13 -> 1.4069984 | L13: 11 | M13: =INT(MOD(main!$T$1*L13,24)*360/24) -> 10 | N13: =MOD(INT(M13*24/360),24) -> 0 | O13: =VLOOKUP($N13,table!$I$3:$V$26,12,FALSE)*$T$1 -> 0.36328125 | P13: =VLOOKUP($N13,table!$I$3:$V$26,13,FALSE)*$T$1 -> 0.36328125 | Q13: =O13-P13 -> 0 | R13: =IF(dft_cos!M$1<1/dft_cos!$A$3, 20*LOG10(1/dft_cos!$A$3),20*LOG10(dft_cos!M$1)) -> -63.795043
A14: 12 | B14: =SIN(6*PI()*A14/24)*main!$B$1 -> 4.9618512e-17 | C14: =SIN(2*PI()*A14/24) -> 1.2251485e-16 | D14: =SIN(2*PI()*A14/24+2*PI()/3) -> -0.8660254 | E14: =C14+$B14 -> 1.7213336e-16 | F14: =D14+$B14 -> -0.8660254 | G14: =E14*$J$1 -> 1.9774842e-16 | H14: =F14*$J$1 -> -0.99489813 | I14: =G14-H14 -> 0.99489813 | L14: 12 | M14: =INT(MOD(main!$T$1*L14,24)*360/24) -> 11 | N14: =MOD(INT(M14*24/360),24) -> 0 | O14: =VLOOKUP($N14,table!$I$3:$V$26,12,FALSE)*$T$1 -> 0.36328125 | P14: =VLOOKUP($N14,table!$I$3:$V$26,13,FALSE)*$T$1 -> 0.36328125 | Q14: =O14-P14 -> 0 | R14: =IF(dft_cos!N$1<1/dft_cos!$A$3, 20*LOG10(1/dft_cos!$A$3),20*LOG10(dft_cos!N$1)) -> -93.9794
A15: 13 | B15: =SIN(6*PI()*A15/24)*main!$B$1 -> -0.095459415 | C15: =SIN(2*PI()*A15/24) -> -0.25881905 | D15: =SIN(2*PI()*A15/24+2*PI()/3) -> -0.70710678 | E15: =C15+$B15 -> -0.35427846 | F15: =D15+$B15 -> -0.8025662 | G15: =E15*$J$1 -> -0.40699843 | H15: =F15*$J$1 -> -0.9219956 | I15: =G15-H15 -> 0.51499717 | L15: 13 | M15: =INT(MOD(main!$T$1*L15,24)*360/24) -> 12 | N15: =MOD(INT(M15*24/360),24) -> 0 | O15: =VLOOKUP($N15,table!$I$3:$V$26,12,FALSE)*$T$1 -> 0.36328125 | P15: =VLOOKUP($N15,table!$I$3:$V$26,13,FALSE)*$T$1 -> 0.36328125 | Q15: =O15-P15 -> 0 | R15: =IF(dft_cos!O$1<1/dft_cos!$A$3, 20*LOG10(1/dft_cos!$A$3),20*LOG10(dft_cos!O$1)) -> -65.241402
A16: 14 | B16: =SIN(6*PI()*A16/24)*main!$B$1 -> -0.135 | C16: =SIN(2*PI()*A16/24) -> -0.5 | D16: =SIN(2*PI()*A16/24+2*PI()/3) -> -0.5 | E16: =C16+$B16 -> -0.635 | F16: =D16+$B16 -> -0.635 | G16: =E16*$J$1 -> -0.72949397 | H16: =F16*$J$1 -> -0.72949397 | I16: =G16-H16 -> 0 | L16: 14 | M16: =INT(MOD(main!$T$1*L16,24)*360/24) -> 13 | N16: =MOD(INT(M16*24/360),24) -> 0 | O16: =VLOOKUP($N16,table!$I$3:$V$26,12,FALSE)*$T$1 -> 0.36328125 | P16: =VLOOKUP($N16,table!$I$3:$V$26,13,FALSE)*$T$1 -> 0.36328125 | Q16: =O16-P16 -> 0 | R16: =IF(dft_cos!P$1<1/dft_cos!$A$3, 20*LOG10(1/dft_cos!$A$3),20*LOG10(dft_cos!P$1)) -> -93.9794
A17: 15 | B17: =SIN(6*PI()*A17/24)*main!$B$1 -> -0.095459415 | C17: =SIN(2*PI()*A17/24) -> -0.70710678 | D17: =SIN(2*PI()*A17/24+2*PI()/3) -> -0.25881905 | E17: =C17+$B17 -> -0.8025662 | F17: =D17+$B17 -> -0.35427846 | G17: =E17*$J$1 -> -0.9219956 | H17: =F17*$J$1 -> -0.40699843 | I17: =G17-H17 -> -0.51499717 | L17: 15 | M17: =INT(MOD(main!$T$1*L17,24)*360/24) -> 14 | N17: =MOD(INT(M17*24/360),24) -> 0 | O17: =VLOOKUP($N17,table!$I$3:$V$26,12,FALSE)*$T$1 -> 0.36328125 | P17: =VLOOKUP($N17,table!$I$3:$V$26,13,FALSE)*$T$1 -> 0.36328125 | Q17: =O17-P17 -> 0 | R17: =IF(dft_cos!Q$1<1/dft_cos!$A$3, 20*LOG10(1/dft_cos!$A$3),20*LOG10(dft_cos!Q$1)) -> -93.9794
A18: 16 | B18: =SIN(6*PI()*A18/24)*main!$B$1 -> -6.6158017e-17 | C18: =SIN(2*PI()*A18/24) -> -0.8660254 | D18: =SIN(2*PI()*A18/24+2*PI()/3) -> -2.4502969e-16 | E18: =C18+$B18 -> -0.8660254 | F18: =D18+$B18 -> -3.1118771e-16 | G18: =E18*$J$1 -> -0.99489813 | H18: =F18*$J$1 -> -3.5749537e-16 | I18: =G18-H18 -> -0.99489813 | L18: 16 | M18: =INT(MOD(main!$T$1*L18,24)*360/24) -> 15 | N18: =MOD(INT(M18*24/360),24) -> 1 | O18: =VLOOKUP($N18,table!$I$3:$V$26,12,FALSE)*$T$1 -> 0.4609375 | P18: =VLOOKUP($N18,table!$I$3:$V$26,13,FALSE)*$T$1 -> 0.203125 | Q18: =O18-P18 -> 0.2578125 | R18: =IF(dft_cos!R$1<1/dft_cos!$A$3, 20*LOG10(1/dft_cos!$A$3),20*LOG10(dft_cos!R$1)) -> -93.9794
A19: 17 | B19: =SIN(6*PI()*A19/24)*main!$B$1 -> 0.095459415 | C19: =SIN(2*PI()*A19/24) -> -0.96592583 | D19: =SIN(2*PI()*A19/24+2*PI()/3) -> 0.25881905 | E19: =C19+$B19 -> -0.87046641 | F19: =D19+$B19 -> 0.35427846 | G19: =E19*$J$1 -> -1 | H19: =F19*$J$1 -> 0.40699843 | I19: =G19-H19 -> -1.4069984 | L19: 17 | M19: =INT(MOD(main!$T$1*L19,24)*360/24) -> 15 | N19: =MOD(INT(M19*24/360),24) -> 1 | O19: =VLOOKUP($N19,table!$I$3:$V$26,12,FALSE)*$T$1 -> 0.4609375 | P19: =VLOOKUP($N19,table!$I$3:$V$26,13,FALSE)*$T$1 -> 0.203125 | Q19: =O19-P19 -> 0.2578125 | R19: =IF(dft_cos!S$1<1/dft_cos!$A$3, 20*LOG10(1/dft_cos!$A$3),20*LOG10(dft_cos!S$1)) -> -70.856652
A20: 18 | B20: =SIN(6*PI()*A20/24)*main!$B$1 -> 0.135 | C20: =SIN(2*PI()*A20/24) -> -1 | D20: =SIN(2*PI()*A20/24+2*PI()/3) -> 0.5 | E20: =C20+$B20 -> -0.865 | F20: =D20+$B20 -> 0.635 | G20: =E20*$J$1 -> -0.99372014 | H20: =F20*$J$1 -> 0.72949397 | I20: =G20-H20 -> -1.7232141 | L20: 18 | M20: =INT(MOD(main!$T$1*L20,24)*360/24) -> 16 | N20: =MOD(INT(M20*24/360),24) -> 1 | O20: =VLOOKUP($N20,table!$I$3:$V$26,12,FALSE)*$T$1 -> 0.4609375 | P20: =VLOOKUP($N20,table!$I$3:$V$26,13,FALSE)*$T$1 -> 0.203125 | Q20: =O20-P20 -> 0.2578125 | R20: =IF(dft_cos!T$1<1/dft_cos!$A$3, 20*LOG10(1/dft_cos!$A$3),20*LOG10(dft_cos!T$1)) -> -93.9794
A21: 19 | B21: =SIN(6*PI()*A21/24)*main!$B$1 -> 0.095459415 | C21: =SIN(2*PI()*A21/24) -> -0.96592583 | D21: =SIN(2*PI()*A21/24+2*PI()/3) -> 0.70710678 | E21: =C21+$B21 -> -0.87046641 | F21: =D21+$B21 -> 0.8025662 | G21: =E21*$J$1 -> -1 | H21: =F21*$J$1 -> 0.9219956 | I21: =G21-H21 -> -1.9219956 | L21: 19 | M21: =INT(MOD(main!$T$1*L21,24)*360/24) -> 17 | N21: =MOD(INT(M21*24/360),24) -> 1 | O21: =VLOOKUP($N21,table!$I$3:$V$26,12,FALSE)*$T$1 -> 0.4609375 | P21: =VLOOKUP($N21,table!$I$3:$V$26,13,FALSE)*$T$1 -> 0.203125 | Q21: =O21-P21 -> 0.2578125 | R21: =IF(dft_cos!U$1<1/dft_cos!$A$3, 20*LOG10(1/dft_cos!$A$3),20*LOG10(dft_cos!U$1)) -> -74.870491
A22: 20 | B22: =SIN(6*PI()*A22/24)*main!$B$1 -> 3.2250569e-16 | C22: =SIN(2*PI()*A22/24) -> -0.8660254 | D22: =SIN(2*PI()*A22/24+2*PI()/3) -> 0.8660254 | E22: =C22+$B22 -> -0.8660254 | F22: =D22+$B22 -> 0.8660254 | G22: =E22*$J$1 -> -0.99489813 | H22: =F22*$J$1 -> 0.99489813 | I22: =G22-H22 -> -1.9897963 | L22: 20 | M22: =INT(MOD(main!$T$1*L22,24)*360/24) -> 18 | N22: =MOD(INT(M22*24/360),24) -> 1 | O22: =VLOOKUP($N22,table!$I$3:$V$26,12,FALSE)*$T$1 -> 0.4609375 | P22: =VLOOKUP($N22,table!$I$3:$V$26,13,FALSE)*$T$1 -> 0.203125 | Q22: =O22-P22 -> 0.2578125 | R22: =IF(dft_cos!V$1<1/dft_cos!$A$3, 20*LOG10(1/dft_cos!$A$3),20*LOG10(dft_cos!V$1)) -> -93.9794
A23: 21 | B23: =SIN(6*PI()*A23/24)*main!$B$1 -> -0.095459415 | C23: =SIN(2*PI()*A23/24) -> -0.70710678 | D23: =SIN(2*PI()*A23/24+2*PI()/3) -> 0.96592583 | E23: =C23+$B23 -> -0.8025662 | F23: =D23+$B23 -> 0.87046641 | G23: =E23*$J$1 -> -0.9219956 | H23: =F23*$J$1 -> 1 | I23: =G23-H23 -> -1.9219956 | L23: 21 | M23: =INT(MOD(main!$T$1*L23,24)*360/24) -> 19 | N23: =MOD(INT(M23*24/360),24) -> 1 | O23: =VLOOKUP($N23,table!$I$3:$V$26,12,FALSE)*$T$1 -> 0.4609375 | P23: =VLOOKUP($N23,table!$I$3:$V$26,13,FALSE)*$T$1 -> 0.203125 | Q23: =O23-P23 -> 0.2578125 | R23: =IF(dft_cos!W$1<1/dft_cos!$A$3, 20*LOG10(1/dft_cos!$A$3),20*LOG10(dft_cos!W$1)) -> -93.9794
A24: 22 | B24: =SIN(6*PI()*A24/24)*main!$B$1 -> -0.135 | C24: =SIN(2*PI()*A24/24) -> -0.5 | D24: =SIN(2*PI()*A24/24+2*PI()/3) -> 1 | E24: =C24+$B24 -> -0.635 | F24: =D24+$B24 -> 0.865 | G24: =E24*$J$1 -> -0.72949397 | H24: =F24*$J$1 -> 0.99372014 | I24: =G24-H24 -> -1.7232141 | L24: 22 | M24: =INT(MOD(main!$T$1*L24,24)*360/24) -> 20 | N24: =MOD(INT(M24*24/360),24) -> 1 | O24: =VLOOKUP($N24,table!$I$3:$V$26,12,FALSE)*$T$1 -> 0.4609375 | P24: =VLOOKUP($N24,table!$I$3:$V$26,13,FALSE)*$T$1 -> 0.203125 | Q24: =O24-P24 -> 0.2578125 | R24: =IF(dft_cos!X$1<1/dft_cos!$A$3, 20*LOG10(1/dft_cos!$A$3),20*LOG10(dft_cos!X$1)) -> -93.9794
A25: 23 | B25: =SIN(6*PI()*A25/24)*main!$B$1 -> -0.095459415 | C25: =SIN(2*PI()*A25/24) -> -0.25881905 | D25: =SIN(2*PI()*A25/24+2*PI()/3) -> 0.96592583 | E25: =C25+$B25 -> -0.35427846 | F25: =D25+$B25 -> 0.87046641 | G25: =E25*$J$1 -> -0.40699843 | H25: =F25*$J$1 -> 1 | I25: =G25-H25 -> -1.4069984 | L25: 23 | M25: =INT(MOD(main!$T$1*L25,24)*360/24) -> 21 | N25: =MOD(INT(M25*24/360),24) -> 1 | O25: =VLOOKUP($N25,table!$I$3:$V$26,12,FALSE)*$T$1 -> 0.4609375 | P25: =VLOOKUP($N25,table!$I$3:$V$26,13,FALSE)*$T$1 -> 0.203125 | Q25: =O25-P25 -> 0.2578125 | R25: =IF(dft_cos!Y$1<1/dft_cos!$A$3, 20*LOG10(1/dft_cos!$A$3),20*LOG10(dft_cos!Y$1)) -> -27.283805
L26: 24 | M26: =INT(MOD(main!$T$1*L26,24)*360/24) -> 22 | N26: =MOD(INT(M26*24/360),24) -> 1 | O26: =VLOOKUP($N26,table!$I$3:$V$26,12,FALSE)*$T$1 -> 0.4609375 | P26: =VLOOKUP($N26,table!$I$3:$V$26,13,FALSE)*$T$1 -> 0.203125 | Q26: =O26-P26 -> 0.2578125 | R26: =IF(dft_cos!Z$1<1/dft_cos!$A$3, 20*LOG10(1/dft_cos!$A$3),20*LOG10(dft_cos!Z$1)) -> -93.9794
L27: 25 | M27: =INT(MOD(main!$T$1*L27,24)*360/24) -> 23 | N27: =MOD(INT(M27*24/360),24) -> 1 | O27: =VLOOKUP($N27,table!$I$3:$V$26,12,FALSE)*$T$1 -> 0.4609375 | P27: =VLOOKUP($N27,table!$I$3:$V$26,13,FALSE)*$T$1 -> 0.203125 | Q27: =O27-P27 -> 0.2578125 | R27: =IF(dft_cos!AA$1<1/dft_cos!$A$3, 20*LOG10(1/dft_cos!$A$3),20*LOG10(dft_cos!AA$1)) -> -27.998723
L28: 26 | M28: =INT(MOD(main!$T$1*L28,24)*360/24) -> 24 | N28: =MOD(INT(M28*24/360),24) -> 1 | O28: =VLOOKUP($N28,table!$I$3:$V$26,12,FALSE)*$T$1 -> 0.4609375 | P28: =VLOOKUP($N28,table!$I$3:$V$26,13,FALSE)*$T$1 -> 0.203125 | Q28: =O28-P28 -> 0.2578125 | R28: =IF(dft_cos!AB$1<1/dft_cos!$A$3, 20*LOG10(1/dft_cos!$A$3),20*LOG10(dft_cos!AB$1)) -> -93.9794
L29: 27 | M29: =INT(MOD(main!$T$1*L29,24)*360/24) -> 25 | N29: =MOD(INT(M29*24/360),24) -> 1 | O29: =VLOOKUP($N29,table!$I$3:$V$26,12,FALSE)*$T$1 -> 0.4609375 | P29: =VLOOKUP($N29,table!$I$3:$V$26,13,FALSE)*$T$1 -> 0.203125 | Q29: =O29-P29 -> 0.2578125 | R29: =IF(dft_cos!AC$1<1/dft_cos!$A$3, 20*LOG10(1/dft_cos!$A$3),20*LOG10(dft_cos!AC$1)) -> -93.9794
L30: 28 | M30: =INT(MOD(main!$T$1*L30,24)*360/24) -> 26 | N30: =MOD(INT(M30*24/360),24) -> 1 | O30: =VLOOKUP($N30,table!$I$3:$V$26,12,FALSE)*$T$1 -> 0.4609375 | P30: =VLOOKUP($N30,table!$I$3:$V$26,13,FALSE)*$T$1 -> 0.203125 | Q30: =O30-P30 -> 0.2578125 | R30: =IF(dft_cos!AD$1<1/dft_cos!$A$3, 20*LOG10(1/dft_cos!$A$3),20*LOG10(dft_cos!AD$1)) -> -93.9794
L31: 29 | M31: =INT(MOD(main!$T$1*L31,24)*360/24) -> 27 | N31: =MOD(INT(M31*24/360),24) -> 1 | O31: =VLOOKUP($N31,table!$I$3:$V$26,12,FALSE)*$T$1 -> 0.4609375 | P31: =VLOOKUP($N31,table!$I$3:$V$26,13,FALSE)*$T$1 -> 0.203125 | Q31: =O31-P31 -> 0.2578125 | R31: =IF(dft_cos!AE$1<1/dft_cos!$A$3, 20*LOG10(1/dft_cos!$A$3),20*LOG10(dft_cos!AE$1)) -> -78.496744
L32: 30 | M32: =INT(MOD(main!$T$1*L32,24)*360/24) -> 28 | N32: =MOD(INT(M32*24/360),24) -> 1 | O32: =VLOOKUP($N32,table!$I$3:$V$26,12,FALSE)*$T$1 -> 0.4609375 | P32: =VLOOKUP($N32,table!$I$3:$V$26,13,FALSE)*$T$1 -> 0.203125 | Q32: =O32-P32 -> 0.2578125 | R32: =IF(dft_cos!AF$1<1/dft_cos!$A$3, 20*LOG10(1/dft_cos!$A$3),20*LOG10(dft_cos!AF$1)) -> -93.9794
L33: 31 | M33: =INT(MOD(main!$T$1*L33,24)*360/24) -> 29 | N33: =MOD(INT(M33*24/360),24) -> 1 | O33: =VLOOKUP($N33,table!$I$3:$V$26,12,FALSE)*$T$1 -> 0.4609375 | P33: =VLOOKUP($N33,table!$I$3:$V$26,13,FALSE)*$T$1 -> 0.203125 | Q33: =O33-P33 -> 0.2578125 | R33: =IF(dft_cos!AG$1<1/dft_cos!$A$3, 20*LOG10(1/dft_cos!$A$3),20*LOG10(dft_cos!AG$1)) -> -76.009611
L34: 32 | M34: =INT(MOD(main!$T$1*L34,24)*360/24) -> 30 | N34: =MOD(INT(M34*24/360),24) -> 2 | O34: =VLOOKUP($N34,table!$I$3:$V$26,12,FALSE)*$T$1 -> 0.49609375 | P34: =VLOOKUP($N34,table!$I$3:$V$26,13,FALSE)*$T$1 -> 0 | Q34: =O34-P34 -> 0.49609375 | R34: =IF(dft_cos!AH$1<1/dft_cos!$A$3, 20*LOG10(1/dft_cos!$A$3),20*LOG10(dft_cos!AH$1)) -> -93.9794
L35: 33 | M35: =INT(MOD(main!$T$1*L35,24)*360/24) -> 30 | N35: =MOD(INT(M35*24/360),24) -> 2 | O35: =VLOOKUP($N35,table!$I$3:$V$26,12,FALSE)*$T$1 -> 0.49609375 | P35: =VLOOKUP($N35,table!$I$3:$V$26,13,FALSE)*$T$1 -> 0 | Q35: =O35-P35 -> 0.49609375 | R35: =IF(dft_cos!AI$1<1/dft_cos!$A$3, 20*LOG10(1/dft_cos!$A$3),20*LOG10(dft_cos!AI$1)) -> -93.9794
L36: 34 | M36: =INT(MOD(main!$T$1*L36,24)*360/24) -> 31 | N36: =MOD(INT(M36*24/360),24) -> 2 | O36: =VLOOKUP($N36,table!$I$3:$V$26,12,FALSE)*$T$1 -> 0.49609375 | P36: =VLOOKUP($N36,table!$I$3:$V$26,13,FALSE)*$T$1 -> 0 | Q36: =O36-P36 -> 0.49609375 | R36: =IF(dft_cos!AJ$1<1/dft_cos!$A$3, 20*LOG10(1/dft_cos!$A$3),20*LOG10(dft_cos!AJ$1)) -> -93.9794
L37: 35 | M37: =INT(MOD(main!$T$1*L37,24)*360/24) -> 32 | N37: =MOD(INT(M37*24/360),24) -> 2 | O37: =VLOOKUP($N37,table!$I$3:$V$26,12,FALSE)*$T$1 -> 0.49609375 | P37: =VLOOKUP($N37,table!$I$3:$V$26,13,FALSE)*$T$1 -> 0 | Q37: =O37-P37 -> 0.49609375 | R37: =IF(dft_cos!AK$1<1/dft_cos!$A$3, 20*LOG10(1/dft_cos!$A$3),20*LOG10(dft_cos!AK$1)) -> -73.741255
L38: 36 | M38: =INT(MOD(main!$T$1*L38,24)*360/24) -> 33 | N38: =MOD(INT(M38*24/360),24) -> 2 | O38: =VLOOKUP($N38,table!$I$3:$V$26,12,FALSE)*$T$1 -> 0.49609375 | P38: =VLOOKUP($N38,table!$I$3:$V$26,13,FALSE)*$T$1 -> 0 | Q38: =O38-P38 -> 0.49609375 | R38: =IF(dft_cos!AL$1<1/dft_cos!$A$3, 20*LOG10(1/dft_cos!$A$3),20*LOG10(dft_cos!AL$1)) -> -93.9794
L39: 37 | M39: =INT(MOD(main!$T$1*L39,24)*360/24) -> 34 | N39: =MOD(INT(M39*24/360),24) -> 2 | O39: =VLOOKUP($N39,table!$I$3:$V$26,12,FALSE)*$T$1 -> 0.49609375 | P39: =VLOOKUP($N39,table!$I$3:$V$26,13,FALSE)*$T$1 -> 0 | Q39: =O39-P39 -> 0.49609375 | R39: =IF(dft_cos!AM$1<1/dft_cos!$A$3, 20*LOG10(1/dft_cos!$A$3),20*LOG10(dft_cos!AM$1)) -> -74.209894
L40: 38 | M40: =INT(MOD(main!$T$1*L40,24)*360/24) -> 35 | N40: =MOD(INT(M40*24/360),24) -> 2 | O40: =VLOOKUP($N40,table!$I$3:$V$26,12,FALSE)*$T$1 -> 0.49609375 | P40: =VLOOKUP($N40,table!$I$3:$V$26,13,FALSE)*$T$1 -> 0 | Q40: =O40-P40 -> 0.49609375 | R40: =IF(dft_cos!AN$1<1/dft_cos!$A$3, 20*LOG10(1/dft_cos!$A$3),20*LOG10(dft_cos!AN$1)) -> -93.9794
...

Sheet dft_cos
B1: =$A$2*SQRT(B3^2+dft_sin!B1^2) -> 0 | C1: =$A$2*SQRT(C3^2+dft_sin!C1^2) -> 0.98849963 | D1: =$A$2*SQRT(D3^2+dft_sin!D1^2) -> 2.905014e-16 | E1: =$A$2*SQRT(E3^2+dft_sin!E1^2) -> 1.1836195e-16 | F1: =$A$2*SQRT(F3^2+dft_sin!F1^2) -> 1.0960028e-16 | G1: =$A$2*SQRT(G3^2+dft_sin!G1^2) -> 0.00068332892 | H1: =$A$2*SQRT(H3^2+dft_sin!H1^2) -> 2.0691825e-17 | I1: =$A$2*SQRT(I3^2+dft_sin!I1^2) -> 0.00069399236 | ... GK1: =$A$2*SQRT(GK3^2+dft_sin!GK1^2) -> 0.0080873241
A2: 1 | B2: =IF(dft_cos!B$1<1/dft_cos!$A$3, 20*LOG10(1/dft_cos!$A$3),20*LOG10(dft_cos!B$1)) -> -93.9794 | C2: =IF(dft_cos!C$1<1/dft_cos!$A$3, 20*LOG10(1/dft_cos!$A$3),20*LOG10(dft_cos!C$1)) -> -0.10046978 | D2: =IF(dft_cos!D$1<1/dft_cos!$A$3, 20*LOG10(1/dft_cos!$A$3),20*LOG10(dft_cos!D$1)) -> -93.9794 | E2: =IF(dft_cos!E$1<1/dft_cos!$A$3, 20*LOG10(1/dft_cos!$A$3),20*LOG10(dft_cos!E$1)) -> -93.9794 | F2: =IF(dft_cos!F$1<1/dft_cos!$A$3, 20*LOG10(1/dft_cos!$A$3),20*LOG10(dft_cos!F$1)) -> -93.9794 | G2: =IF(dft_cos!G$1<1/dft_cos!$A$3, 20*LOG10(1/dft_cos!$A$3),20*LOG10(dft_cos!G$1)) -> -63.307404 | H2: =IF(dft_cos!H$1<1/dft_cos!$A$3, 20*LOG10(1/dft_cos!$A$3),20*LOG10(dft_cos!H$1)) -> -93.9794 | I2: =IF(dft_cos!I$1<1/dft_cos!$A$3, 20*LOG10(1/dft_cos!$A$3),20*LOG10(dft_cos!I$1)) -> -63.172906 | ... GK2: =IF(dft_cos!GK$1<1/dft_cos!$A$3, 20*LOG10(1/dft_cos!$A$3),20*LOG10(dft_cos!GK$1)) -> -41.843903
A3: 50000 | B3: =SUM(B5:B1002)*2/$A$4 -> 0 | C3: =SUM(C5:C1002)*2/$A$4 -> -0.12100291 | D3: =SUM(D5:D1002)*2/$A$4 -> -5.4354669e-17 | E3: =SUM(E5:E1002)*2/$A$4 -> 1.0090308e-16 | F3: =SUM(F5:F1002)*2/$A$4 -> -2.0238441e-17 | G3: =SUM(G5:G1002)*2/$A$4 -> -0.00039346639 | H3: =SUM(H5:H1002)*2/$A$4 -> 1.994932e-17 | I3: =SUM(I5:I1002)*2/$A$4 -> -0.00052549715 | ... GK3: =SUM(GK5:GK1002)*2/$A$4 -> 0.0080265037
A4: =192*2 -> 384 | B4: 0 | C4: 1 | D4: 2 | E4: 3 | F4: 4 | G4: 5 | H4: 6 | I4: 7 | J4: 8 | K4: 9 | L4: 10 | M4: 11 | N4: 12 | O4: 13 | P4: 14 | Q4: 15 | R4: 16 | S4: 17 | T4: 18 | U4: 19 | V4: 20 | W4: 21 | X4: 22 | Y4: 23 | Z4: 24 | AA4: 25 | AB4: 26 | AC4: 27 | AD4: 28 | AE4: 29 | AF4: 30 | AG4: 31 | AH4: 32 | AI4: 33 | AJ4: 34 | AK4: 35 | AL4: 36 | AM4: 37 | AN4: 38 | AO4: 39 | AP4: 40 | AQ4: 41 | AR4: 42 | AS4: 43 | AT4: 44 | AU4: 45 | AV4: 46 | AW4: 47 | AX4: 48 | AY4: 49 | AZ4: 50 | BA4: 51 | BB4: 52 | BC4: 53 | BD4: 54 | BE4: 55 | BF4: 56 | BG4: 57 | BH4: 58 | BI4: 59 | BJ4: 60 | BK4: 61 | BL4: 62 | BM4: 63 | BN4: 64 | BO4: 65 | BP4: 66 | BQ4: 67 | BR4: 68 | BS4: 69 | BT4: 70 | BU4: 71 | BV4: 72 | BW4: 73 | BX4: 74 | BY4: 75 | BZ4: 76 | CA4: 77 | CB4: 78 | CC4: 79 | CD4: 80 | CE4: 81 | CF4: 82 | CG4: 83 | CH4: 84 | CI4: 85 | CJ4: 86 | CK4: 87 | CL4: 88 | CM4: 89 | CN4: 90 | CO4: 91 | CP4: 92 | CQ4: 93 | CR4: 94 | CS4: 95 | CT4: 96 | CU4: 97 | CV4: 98 | CW4: 99 | CX4: 100 | CY4: 101 | CZ4: 102 | DA4: 103 | DB4: 104 | DC4: 105 | DD4: 106 | DE4: 107 | DF4: 108 | DG4: 109 | DH4: 110 | DI4: 111 | DJ4: 112 | DK4: 113 | DL4: 114 | DM4: 115 | DN4: 116 | DO4: 117 | DP4: 118 | DQ4: 119 | DR4: 120 | DS4: 121 | DT4: 122 | DU4: 123 | DV4: 124 | DW4: 125 | DX4: 126 | DY4: 127 | DZ4: 128 | EA4: 129 | EB4: 130 | EC4: 131 | ED4: 132 | EE4: 133 | EF4: 134 | EG4: 135 | EH4: 136 | EI4: 137 | EJ4: 138 | EK4: 139 | EL4: 140 | EM4: 141 | EN4: 142 | EO4: 143 | EP4: 144 | EQ4: 145 | ER4: 146 | ES4: 147 | ET4: 148 | EU4: 149 | EV4: 150 | EW4: 151 | EX4: 152 | EY4: 153 | EZ4: 154 | FA4: 155 | FB4: 156 | FC4: 157 | FD4: 158 | FE4: 159 | FF4: 160 | FG4: 161 | FH4: 162 | FI4: 163 | FJ4: 164 | FK4: 165 | FL4: 166 | FM4: 167 | FN4: 168 | FO4: 169 | FP4: 170 | FQ4: 171 | FR4: 172 | FS4: 173 | FT4: 174 | FU4: 175 | FV4: 176 | FW4: 177 | FX4: 178 | FY4: 179 | FZ4: 180 | GA4: 181 | GB4: 182 | GC4: 183 | GD4: 184 | GE4: 185 | GF4: 186 | GG4: 187 | GH4: 188 | GI4: 189 | GJ4: 190 | GK4: 191
A5: 0 | B5: =COS(2*PI()*B$4*$A5/$A$4)*value!$Q2 -> 0 | C5: =COS(2*PI()*C$4*$A5/$A$4)*value!$Q2 -> 0 | D5: =COS(2*PI()*D$4*$A5/$A$4)*value!$Q2 -> 0 | E5: =COS(2*PI()*E$4*$A5/$A$4)*value!$Q2 -> 0 | F5: =COS(2*PI()*F$4*$A5/$A$4)*value!$Q2 -> 0 | G5: =COS(2*PI()*G$4*$A5/$A$4)*value!$Q2 -> 0 | H5: =COS(2*PI()*H$4*$A5/$A$4)*value!$Q2 -> 0 | I5: =COS(2*PI()*I$4*$A5/$A$4)*value!$Q2 -> 0 | ... GK5: =COS(2*PI()*GK$4*$A5/$A$4)*value!$Q2 -> 0
A6: 1 | B6: =COS(2*PI()*B$4*$A6/$A$4)*value!$Q3 -> 0 | C6: =COS(2*PI()*C$4*$A6/$A$4)*value!$Q3 -> 0 | D6: =COS(2*PI()*D$4*$A6/$A$4)*value!$Q3 -> 0 | E6: =COS(2*PI()*E$4*$A6/$A$4)*value!$Q3 -> 0 | F6: =COS(2*PI()*F$4*$A6/$A$4)*value!$Q3 -> 0 | G6: =COS(2*PI()*G$4*$A6/$A$4)*value!$Q3 -> 0 | H6: =COS(2*PI()*H$4*$A6/$A$4)*value!$Q3 -> 0 | I6: =COS(2*PI()*I$4*$A6/$A$4)*value!$Q3 -> 0 | ... GK6: =COS(2*PI()*GK$4*$A6/$A$4)*value!$Q3 -> 0
A7: 2 | B7: =COS(2*PI()*B$4*$A7/$A$4)*value!$Q4 -> 0 | C7: =COS(2*PI()*C$4*$A7/$A$4)*value!$Q4 -> 0 | D7: =COS(2*PI()*D$4*$A7/$A$4)*value!$Q4 -> 0 | E7: =COS(2*PI()*E$4*$A7/$A$4)*value!$Q4 -> 0 | F7: =COS(2*PI()*F$4*$A7/$A$4)*value!$Q4 -> 0 | G7: =COS(2*PI()*G$4*$A7/$A$4)*value!$Q4 -> 0 | H7: =COS(2*PI()*H$4*$A7/$A$4)*value!$Q4 -> 0 | I7: =COS(2*PI()*I$4*$A7/$A$4)*value!$Q4 -> 0 | ... GK7: =COS(2*PI()*GK$4*$A7/$A$4)*value!$Q4 -> 0
A8: 3 | B8: =COS(2*PI()*B$4*$A8/$A$4)*value!$Q5 -> 0 | C8: =COS(2*PI()*C$4*$A8/$A$4)*value!$Q5 -> 0 | D8: =COS(2*PI()*D$4*$A8/$A$4)*value!$Q5 -> 0 | E8: =COS(2*PI()*E$4*$A8/$A$4)*value!$Q5 -> 0 | F8: =COS(2*PI()*F$4*$A8/$A$4)*value!$Q5 -> 0 | G8: =COS(2*PI()*G$4*$A8/$A$4)*value!$Q5 -> 0 | H8: =COS(2*PI()*H$4*$A8/$A$4)*value!$Q5 -> 0 | I8: =COS(2*PI()*I$4*$A8/$A$4)*value!$Q5 -> 0 | ... GK8: =COS(2*PI()*GK$4*$A8/$A$4)*value!$Q5 -> 0
A9: 4 | B9: =COS(2*PI()*B$4*$A9/$A$4)*value!$Q6 -> 0 | C9: =COS(2*PI()*C$4*$A9/$A$4)*value!$Q6 -> 0 | D9: =COS(2*PI()*D$4*$A9/$A$4)*value!$Q6 -> 0 | E9: =COS(2*PI()*E$4*$A9/$A$4)*value!$Q6 -> 0 | F9: =COS(2*PI()*F$4*$A9/$A$4)*value!$Q6 -> 0 | G9: =COS(2*PI()*G$4*$A9/$A$4)*value!$Q6 -> 0 | H9: =COS(2*PI()*H$4*$A9/$A$4)*value!$Q6 -> 0 | I9: =COS(2*PI()*I$4*$A9/$A$4)*value!$Q6 -> 0 | ... GK9: =COS(2*PI()*GK$4*$A9/$A$4)*value!$Q6 -> 0
A10: 5 | B10: =COS(2*PI()*B$4*$A10/$A$4)*value!$Q7 -> 0 | C10: =COS(2*PI()*C$4*$A10/$A$4)*value!$Q7 -> 0 | D10: =COS(2*PI()*D$4*$A10/$A$4)*value!$Q7 -> 0 | E10: =COS(2*PI()*E$4*$A10/$A$4)*value!$Q7 -> 0 | F10: =COS(2*PI()*F$4*$A10/$A$4)*value!$Q7 -> 0 | G10: =COS(2*PI()*G$4*$A10/$A$4)*value!$Q7 -> 0 | H10: =COS(2*PI()*H$4*$A10/$A$4)*value!$Q7 -> 0 | I10: =COS(2*PI()*I$4*$A10/$A$4)*value!$Q7 -> 0 | ... GK10: =COS(2*PI()*GK$4*$A10/$A$4)*value!$Q7 -> 0
A11: 6 | B11: =COS(2*PI()*B$4*$A11/$A$4)*value!$Q8 -> 0 | C11: =COS(2*PI()*C$4*$A11/$A$4)*value!$Q8 -> 0 | D11: =COS(2*PI()*D$4*$A11/$A$4)*value!$Q8 -> 0 | E11: =COS(2*PI()*E$4*$A11/$A$4)*value!$Q8 -> 0 | F11: =COS(2*PI()*F$4*$A11/$A$4)*value!$Q8 -> 0 | G11: =COS(2*PI()*G$4*$A11/$A$4)*value!$Q8 -> 0 | H11: =COS(2*PI()*H$4*$A11/$A$4)*value!$Q8 -> 0 | I11: =COS(2*PI()*I$4*$A11/$A$4)*value!$Q8 -> 0 | ... GK11: =COS(2*PI()*GK$4*$A11/$A$4)*value!$Q8 -> 0
A12: 7 | B12: =COS(2*PI()*B$4*$A12/$A$4)*value!$Q9 -> 0 | C12: =COS(2*PI()*C$4*$A12/$A$4)*value!$Q9 -> 0 | D12: =COS(2*PI()*D$4*$A12/$A$4)*value!$Q9 -> 0 | E12: =COS(2*PI()*E$4*$A12/$A$4)*value!$Q9 -> 0 | F12: =COS(2*PI()*F$4*$A12/$A$4)*value!$Q9 -> 0 | G12: =COS(2*PI()*G$4*$A12/$A$4)*value!$Q9 -> 0 | H12: =COS(2*PI()*H$4*$A12/$A$4)*value!$Q9 -> 0 | I12: =COS(2*PI()*I$4*$A12/$A$4)*value!$Q9 -> 0 | ... GK12: =COS(2*PI()*GK$4*$A12/$A$4)*value!$Q9 -> 0
A13: 8 | B13: =COS(2*PI()*B$4*$A13/$A$4)*value!$Q10 -> 0 | C13: =COS(2*PI()*C$4*$A13/$A$4)*value!$Q10 -> 0 | D13: =COS(2*PI()*D$4*$A13/$A$4)*value!$Q10 -> 0 | E13: =COS(2*PI()*E$4*$A13/$A$4)*value!$Q10 -> 0 | F13: =COS(2*PI()*F$4*$A13/$A$4)*value!$Q10 -> 0 | G13: =COS(2*PI()*G$4*$A13/$A$4)*value!$Q10 -> 0 | H13: =COS(2*PI()*H$4*$A13/$A$4)*value!$Q10 -> 0 | I13: =COS(2*PI()*I$4*$A13/$A$4)*value!$Q10 -> 0 | ... GK13: =COS(2*PI()*GK$4*$A13/$A$4)*value!$Q10 -> 0
A14: 9 | B14: =COS(2*PI()*B$4*$A14/$A$4)*value!$Q11 -> 0 | C14: =COS(2*PI()*C$4*$A14/$A$4)*value!$Q11 -> 0 | D14: =COS(2*PI()*D$4*$A14/$A$4)*value!$Q11 -> 0 | E14: =COS(2*PI()*E$4*$A14/$A$4)*value!$Q11 -> 0 | F14: =COS(2*PI()*F$4*$A14/$A$4)*value!$Q11 -> 0 | G14: =COS(2*PI()*G$4*$A14/$A$4)*value!$Q11 -> 0 | H14: =COS(2*PI()*H$4*$A14/$A$4)*value!$Q11 -> 0 | I14: =COS(2*PI()*I$4*$A14/$A$4)*value!$Q11 -> 0 | ... GK14: =COS(2*PI()*GK$4*$A14/$A$4)*value!$Q11 -> 0
A15: 10 | B15: =COS(2*PI()*B$4*$A15/$A$4)*value!$Q12 -> 0 | C15: =COS(2*PI()*C$4*$A15/$A$4)*value!$Q12 -> 0 | D15: =COS(2*PI()*D$4*$A15/$A$4)*value!$Q12 -> 0 | E15: =COS(2*PI()*E$4*$A15/$A$4)*value!$Q12 -> 0 | F15: =COS(2*PI()*F$4*$A15/$A$4)*value!$Q12 -> 0 | G15: =COS(2*PI()*G$4*$A15/$A$4)*value!$Q12 -> 0 | H15: =COS(2*PI()*H$4*$A15/$A$4)*value!$Q12 -> 0 | I15: =COS(2*PI()*I$4*$A15/$A$4)*value!$Q12 -> 0 | ... GK15: =COS(2*PI()*GK$4*$A15/$A$4)*value!$Q12 -> 0
A16: 11 | B16: =COS(2*PI()*B$4*$A16/$A$4)*value!$Q13 -> 0 | C16: =COS(2*PI()*C$4*$A16/$A$4)*value!$Q13 -> 0 | D16: =COS(2*PI()*D$4*$A16/$A$4)*value!$Q13 -> 0 | E16: =COS(2*PI()*E$4*$A16/$A$4)*value!$Q13 -> 0 | F16: =COS(2*PI()*F$4*$A16/$A$4)*value!$Q13 -> 0 | G16: =COS(2*PI()*G$4*$A16/$A$4)*value!$Q13 -> 0 | H16: =COS(2*PI()*H$4*$A16/$A$4)*value!$Q13 -> 0 | I16: =COS(2*PI()*I$4*$A16/$A$4)*value!$Q13 -> 0 | ... GK16: =COS(2*PI()*GK$4*$A16/$A$4)*value!$Q13 -> 0
... A388: 383 | B388: =COS(2*PI()*B$4*$A388/$A$4)*value!$Q385 -> -0.2578125 | C388: =COS(2*PI()*C$4*$A388/$A$4)*value!$Q385 -> -0.25777799 | D388: =COS(2*PI()*D$4*$A388/$A$4)*value!$Q385 -> -0.25767446 | E388: =COS(2*PI()*E$4*$A388/$A$4)*value!$Q385 -> -0.25750195 | F388: =COS(2*PI()*F$4*$A388/$A$4)*value!$Q385 -> -0.2572605 | G388: =COS(2*PI()*G$4*$A388/$A$4)*value!$Q385 -> -0.25695018 | H388: =COS(2*PI()*H$4*$A388/$A$4)*value!$Q385 -> -0.25657106 | I388: =COS(2*PI()*I$4*$A388/$A$4)*value!$Q385 -> -0.25612326 | ... GK388: =COS(2*PI()*GK$4*$A388/$A$4)*value!$Q385 -> 0.25777799

Sheet dft_sin
B1: =SUM(B3:B1000)*2/$A$2 -> 0 | C1: =SUM(C3:C1000)*2/$A$2 -> 0.98106565 | D1: =SUM(D3:D1000)*2/$A$2 -> -2.8537105e-16 | E1: =SUM(E3:E1000)*2/$A$2 -> 6.1871804e-17 | F1: =SUM(F3:F1000)*2/$A$2 -> -1.0771549e-16 | G1: =SUM(G3:G1000)*2/$A$2 -> 0.00055867934 | H1: =SUM(H3:H1000)*2/$A$2 -> -5.493291e-18 | I1: =SUM(I3:I1000)*2/$A$2 -> 0.00045329696 | ... GK1: =SUM(GK3:GK1000)*2/$A$2 -> -0.00098997481
A2: =dft_cos!A4 -> 384 | B2: 0 | C2: 1 | D2: 2 | E2: 3 | F2: 4 | G2: 5 | H2: 6 | I2: 7 | J2: 8 | K2: 9 | L2: 10 | M2: 11 | N2: 12 | O2: 13 | P2: 14 | Q2: 15 | R2: 16 | S2: 17 | T2: 18 | U2: 19 | V2: 20 | W2: 21 | X2: 22 | Y2: 23 | Z2: 24 | AA2: 25 | AB2: 26 | AC2: 27 | AD2: 28 | AE2: 29 | AF2: 30 | AG2: 31 | AH2: 32 | AI2: 33 | AJ2: 34 | AK2: 35 | AL2: 36 | AM2: 37 | AN2: 38 | AO2: 39 | AP2: 40 | AQ2: 41 | AR2: 42 | AS2: 43 | AT2: 44 | AU2: 45 | AV2: 46 | AW2: 47 | AX2: 48 | AY2: 49 | AZ2: 50 | BA2: 51 | BB2: 52 | BC2: 53 | BD2: 54 | BE2: 55 | BF2: 56 | BG2: 57 | BH2: 58 | BI2: 59 | BJ2: 60 | BK2: 61 | BL2: 62 | BM2: 63 | BN2: 64 | BO2: 65 | BP2: 66 | BQ2: 67 | BR2: 68 | BS2: 69 | BT2: 70 | BU2: 71 | BV2: 72 | BW2: 73 | BX2: 74 | BY2: 75 | BZ2: 76 | CA2: 77 | CB2: 78 | CC2: 79 | CD2: 80 | CE2: 81 | CF2: 82 | CG2: 83 | CH2: 84 | CI2: 85 | CJ2: 86 | CK2: 87 | CL2: 88 | CM2: 89 | CN2: 90 | CO2: 91 | CP2: 92 | CQ2: 93 | CR2: 94 | CS2: 95 | CT2: 96 | CU2: 97 | CV2: 98 | CW2: 99 | CX2: 100 | CY2: 101 | CZ2: 102 | DA2: 103 | DB2: 104 | DC2: 105 | DD2: 106 | DE2: 107 | DF2: 108 | DG2: 109 | DH2: 110 | DI2: 111 | DJ2: 112 | DK2: 113 | DL2: 114 | DM2: 115 | DN2: 116 | DO2: 117 | DP2: 118 | DQ2: 119 | DR2: 120 | DS2: 121 | DT2: 122 | DU2: 123 | DV2: 124 | DW2: 125 | DX2: 126 | DY2: 127 | DZ2: 128 | EA2: 129 | EB2: 130 | EC2: 131 | ED2: 132 | EE2: 133 | EF2: 134 | EG2: 135 | EH2: 136 | EI2: 137 | EJ2: 138 | EK2: 139 | EL2: 140 | EM2: 141 | EN2: 142 | EO2: 143 | EP2: 144 | EQ2: 145 | ER2: 146 | ES2: 147 | ET2: 148 | EU2: 149 | EV2: 150 | EW2: 151 | EX2: 152 | EY2: 153 | EZ2: 154 | FA2: 155 | FB2: 156 | FC2: 157 | FD2: 158 | FE2: 159 | FF2: 160 | FG2: 161 | FH2: 162 | FI2: 163 | FJ2: 164 | FK2: 165 | FL2: 166 | FM2: 167 | FN2: 168 | FO2: 169 | FP2: 170 | FQ2: 171 | FR2: 172 | FS2: 173 | FT2: 174 | FU2: 175 | FV2: 176 | FW2: 177 | FX2: 178 | FY2: 179 | FZ2: 180 | GA2: 181 | GB2: 182 | GC2: 183 | GD2: 184 | GE2: 185 | GF2: 186 | GG2: 187 | GH2: 188 | GI2: 189 | GJ2: 190 | GK2: 191
A3: 0 | B3: =SIN(2*PI()*B$2*$A3/$A$2)*value!$Q2 -> 0 | C3: =SIN(2*PI()*C$2*$A3/$A$2)*value!$Q2 -> 0 | D3: =SIN(2*PI()*D$2*$A3/$A$2)*value!$Q2 -> 0 | E3: =SIN(2*PI()*E$2*$A3/$A$2)*value!$Q2 -> 0 | F3: =SIN(2*PI()*F$2*$A3/$A$2)*value!$Q2 -> 0 | G3: =SIN(2*PI()*G$2*$A3/$A$2)*value!$Q2 -> 0 | H3: =SIN(2*PI()*H$2*$A3/$A$2)*value!$Q2 -> 0 | I3: =SIN(2*PI()*I$2*$A3/$A$2)*value!$Q2 -> 0 | ... GK3: =SIN(2*PI()*GK$2*$A3/$A$2)*value!$Q2 -> 0
A4: 1 | B4: =SIN(2*PI()*B$2*$A4/$A$2)*value!$Q3 -> 0 | C4: =SIN(2*PI()*C$2*$A4/$A$2)*value!$Q3 -> 0 | D4: =SIN(2*PI()*D$2*$A4/$A$2)*value!$Q3 -> 0 | E4: =SIN(2*PI()*E$2*$A4/$A$2)*value!$Q3 -> 0 | F4: =SIN(2*PI()*F$2*$A4/$A$2)*value!$Q3 -> 0 | G4: =SIN(2*PI()*G$2*$A4/$A$2)*value!$Q3 -> 0 | H4: =SIN(2*PI()*H$2*$A4/$A$2)*value!$Q3 -> 0 | I4: =SIN(2*PI()*I$2*$A4/$A$2)*value!$Q3 -> 0 | ... GK4: =SIN(2*PI()*GK$2*$A4/$A$2)*value!$Q3 -> 0
A5: 2 | B5: =SIN(2*PI()*B$2*$A5/$A$2)*value!$Q4 -> 0 | C5: =SIN(2*PI()*C$2*$A5/$A$2)*value!$Q4 -> 0 | D5: =SIN(2*PI()*D$2*$A5/$A$2)*value!$Q4 -> 0 | E5: =SIN(2*PI()*E$2*$A5/$A$2)*value!$Q4 -> 0 | F5: =SIN(2*PI()*F$2*$A5/$A$2)*value!$Q4 -> 0 | G5: =SIN(2*PI()*G$2*$A5/$A$2)*value!$Q4 -> 0 | H5: =SIN(2*PI()*H$2*$A5/$A$2)*value!$Q4 -> 0 | I5: =SIN(2*PI()*I$2*$A5/$A$2)*value!$Q4 -> 0 | ... GK5: =SIN(2*PI()*GK$2*$A5/$A$2)*value!$Q4 -> 0
A6: 3 | B6: =SIN(2*PI()*B$2*$A6/$A$2)*value!$Q5 -> 0 | C6: =SIN(2*PI()*C$2*$A6/$A$2)*value!$Q5 -> 0 | D6: =SIN(2*PI()*D$2*$A6/$A$2)*value!$Q5 -> 0 | E6: =SIN(2*PI()*E$2*$A6/$A$2)*value!$Q5 -> 0 | F6: =SIN(2*PI()*F$2*$A6/$A$2)*value!$Q5 -> 0 | G6: =SIN(2*PI()*G$2*$A6/$A$2)*value!$Q5 -> 0 | H6: =SIN(2*PI()*H$2*$A6/$A$2)*value!$Q5 -> 0 | I6: =SIN(2*PI()*I$2*$A6/$A$2)*value!$Q5 -> 0 | ... GK6: =SIN(2*PI()*GK$2*$A6/$A$2)*value!$Q5 -> 0
A7: 4 | B7: =SIN(2*PI()*B$2*$A7/$A$2)*value!$Q6 -> 0 | C7: =SIN(2*PI()*C$2*$A7/$A$2)*value!$Q6 -> 0 | D7: =SIN(2*PI()*D$2*$A7/$A$2)*value!$Q6 -> 0 | E7: =SIN(2*PI()*E$2*$A7/$A$2)*value!$Q6 -> 0 | F7: =SIN(2*PI()*F$2*$A7/$A$2)*value!$Q6 -> 0 | G7: =SIN(2*PI()*G$2*$A7/$A$2)*value!$Q6 -> 0 | H7: =SIN(2*PI()*H$2*$A7/$A$2)*value!$Q6 -> 0 | I7: =SIN(2*PI()*I$2*$A7/$A$2)*value!$Q6 -> 0 | ... GK7: =SIN(2*PI()*GK$2*$A7/$A$2)*value!$Q6 -> 0
A8: 5 | B8: =SIN(2*PI()*B$2*$A8/$A$2)*value!$Q7 -> 0 | C8: =SIN(2*PI()*C$2*$A8/$A$2)*value!$Q7 -> 0 | D8: =SIN(2*PI()*D$2*$A8/$A$2)*value!$Q7 -> 0 | E8: =SIN(2*PI()*E$2*$A8/$A$2)*value!$Q7 -> 0 | F8: =SIN(2*PI()*F$2*$A8/$A$2)*value!$Q7 -> 0 | G8: =SIN(2*PI()*G$2*$A8/$A$2)*value!$Q7 -> 0 | H8: =SIN(2*PI()*H$2*$A8/$A$2)*value!$Q7 -> 0 | I8: =SIN(2*PI()*I$2*$A8/$A$2)*value!$Q7 -> 0 | ... GK8: =SIN(2*PI()*GK$2*$A8/$A$2)*value!$Q7 -> 0
A9: 6 | B9: =SIN(2*PI()*B$2*$A9/$A$2)*value!$Q8 -> 0 | C9: =SIN(2*PI()*C$2*$A9/$A$2)*value!$Q8 -> 0 | D9: =SIN(2*PI()*D$2*$A9/$A$2)*value!$Q8 -> 0 | E9: =SIN(2*PI()*E$2*$A9/$A$2)*value!$Q8 -> 0 | F9: =SIN(2*PI()*F$2*$A9/$A$2)*value!$Q8 -> 0 | G9: =SIN(2*PI()*G$2*$A9/$A$2)*value!$Q8 -> 0 | H9: =SIN(2*PI()*H$2*$A9/$A$2)*value!$Q8 -> 0 | I9: =SIN(2*PI()*I$2*$A9/$A$2)*value!$Q8 -> 0 | ... GK9: =SIN(2*PI()*GK$2*$A9/$A$2)*value!$Q8 -> 0
A10: 7 | B10: =SIN(2*PI()*B$2*$A10/$A$2)*value!$Q9 -> 0 | C10: =SIN(2*PI()*C$2*$A10/$A$2)*value!$Q9 -> 0 | D10: =SIN(2*PI()*D$2*$A10/$A$2)*value!$Q9 -> 0 | E10: =SIN(2*PI()*E$2*$A10/$A$2)*value!$Q9 -> 0 | F10: =SIN(2*PI()*F$2*$A10/$A$2)*value!$Q9 -> 0 | G10: =SIN(2*PI()*G$2*$A10/$A$2)*value!$Q9 -> 0 | H10: =SIN(2*PI()*H$2*$A10/$A$2)*value!$Q9 -> 0 | I10: =SIN(2*PI()*I$2*$A10/$A$2)*value!$Q9 -> 0 | ... GK10: =SIN(2*PI()*GK$2*$A10/$A$2)*value!$Q9 -> 0
A11: 8 | B11: =SIN(2*PI()*B$2*$A11/$A$2)*value!$Q10 -> 0 | C11: =SIN(2*PI()*C$2*$A11/$A$2)*value!$Q10 -> 0 | D11: =SIN(2*PI()*D$2*$A11/$A$2)*value!$Q10 -> 0 | E11: =SIN(2*PI()*E$2*$A11/$A$2)*value!$Q10 -> 0 | F11: =SIN(2*PI()*F$2*$A11/$A$2)*value!$Q10 -> 0 | G11: =SIN(2*PI()*G$2*$A11/$A$2)*value!$Q10 -> 0 | H11: =SIN(2*PI()*H$2*$A11/$A$2)*value!$Q10 -> 0 | I11: =SIN(2*PI()*I$2*$A11/$A$2)*value!$Q10 -> 0 | ... GK11: =SIN(2*PI()*GK$2*$A11/$A$2)*value!$Q10 -> 0
A12: 9 | B12: =SIN(2*PI()*B$2*$A12/$A$2)*value!$Q11 -> 0 | C12: =SIN(2*PI()*C$2*$A12/$A$2)*value!$Q11 -> 0 | D12: =SIN(2*PI()*D$2*$A12/$A$2)*value!$Q11 -> 0 | E12: =SIN(2*PI()*E$2*$A12/$A$2)*value!$Q11 -> 0 | F12: =SIN(2*PI()*F$2*$A12/$A$2)*value!$Q11 -> 0 | G12: =SIN(2*PI()*G$2*$A12/$A$2)*value!$Q11 -> 0 | H12: =SIN(2*PI()*H$2*$A12/$A$2)*value!$Q11 -> 0 | I12: =SIN(2*PI()*I$2*$A12/$A$2)*value!$Q11 -> 0 | ... GK12: =SIN(2*PI()*GK$2*$A12/$A$2)*value!$Q11 -> 0
A13: 10 | B13: =SIN(2*PI()*B$2*$A13/$A$2)*value!$Q12 -> 0 | C13: =SIN(2*PI()*C$2*$A13/$A$2)*value!$Q12 -> 0 | D13: =SIN(2*PI()*D$2*$A13/$A$2)*value!$Q12 -> 0 | E13: =SIN(2*PI()*E$2*$A13/$A$2)*value!$Q12 -> 0 | F13: =SIN(2*PI()*F$2*$A13/$A$2)*value!$Q12 -> 0 | G13: =SIN(2*PI()*G$2*$A13/$A$2)*value!$Q12 -> 0 | H13: =SIN(2*PI()*H$2*$A13/$A$2)*value!$Q12 -> 0 | I13: =SIN(2*PI()*I$2*$A13/$A$2)*value!$Q12 -> 0 | ... GK13: =SIN(2*PI()*GK$2*$A13/$A$2)*value!$Q12 -> 0
A14: 11 | B14: =SIN(2*PI()*B$2*$A14/$A$2)*value!$Q13 -> 0 | C14: =SIN(2*PI()*C$2*$A14/$A$2)*value!$Q13 -> 0 | D14: =SIN(2*PI()*D$2*$A14/$A$2)*value!$Q13 -> 0 | E14: =SIN(2*PI()*E$2*$A14/$A$2)*value!$Q13 -> 0 | F14: =SIN(2*PI()*F$2*$A14/$A$2)*value!$Q13 -> 0 | G14: =SIN(2*PI()*G$2*$A14/$A$2)*value!$Q13 -> 0 | H14: =SIN(2*PI()*H$2*$A14/$A$2)*value!$Q13 -> 0 | I14: =SIN(2*PI()*I$2*$A14/$A$2)*value!$Q13 -> 0 | ... GK14: =SIN(2*PI()*GK$2*$A14/$A$2)*value!$Q13 -> 0
... A386: 383 | B386: =SIN(2*PI()*B$2*$A386/$A$2)*value!$Q385 -> 0 | C386: =SIN(2*PI()*C$2*$A386/$A$2)*value!$Q385 -> 0.0042182589 | D386: =SIN(2*PI()*D$2*$A386/$A$2)*value!$Q385 -> 0.0084353885 | E386: =SIN(2*PI()*E$2*$A386/$A$2)*value!$Q385 -> 0.01265026 | F386: =SIN(2*PI()*F$2*$A386/$A$2)*value!$Q385 -> 0.016861744 | G386: =SIN(2*PI()*G$2*$A386/$A$2)*value!$Q385 -> 0.021068714 | H386: =SIN(2*PI()*H$2*$A386/$A$2)*value!$Q385 -> 0.025270044 | I386: =SIN(2*PI()*I$2*$A386/$A$2)*value!$Q385 -> 0.029464608 | ... GK386: =SIN(2*PI()*GK$2*$A386/$A$2)*value!$Q385 -> 0.0042182589
